Workbook

Sheet clean_historis
A1: no | B1: nomor_ruas | C1: nama_ruas | D1: nama_ruas_norm | E1: desa_yang_dilalui | F1: kecamatan_yang_dilalui | G1: jumlah_desa_yang_dilalui | H1: jumlah_kecamatan_yang_dilalui | I1: jumlah_penduduk_dilayani | J1: terhubung_ruas_provinsi | K1: terhubung_ruas_nasional | L1: jarak_pasar_m | M1: jarak_puskesmas_m | N1: jarak_rsud_m | O1: jarak_sd_smp_m | P1: jarak_ibukota_m | Q1: akses_terputus_ibukota | R1: akses_terputus_pasar | S1: akses_terputus_puskesmas | T1: akses_terputus_rsud | U1: akses_terputus_sd_smp | V1: panjang_km_2023 | W1: lebar_m_2023 | X1: hotmix_km_2023 | Y1: lapen_km_2023 | Z1: beton_km_2023 | AA1: telford_kerikil_km_2023 | AB1: tanah_belum_tembus_km_2023 | AC1: baik_km_2023 | AD1: sedang_km_2023 | AE1: rusak_ringan_km_2023 | AF1: rusak_berat_km_2023 | AG1: jalan_mantap_pct_2023 | AH1: panjang_km_2024 | AI1: lebar_m_2024 | AJ1: hotmix_km_2024 | AK1: lapen_km_2024 | AL1: beton_km_2024 | AM1: telford_kerikil_km_2024 | AN1: tanah_belum_tembus_km_2024 | AO1: baik_km_2024 | AP1: sedang_km_2024 | AQ1: rusak_ringan_km_2024 | AR1: rusak_berat_km_2024 | AS1: jalan_mantap_pct_2024 | AT1: panjang_survei_km_2025 | AU1: beton_km_2025 | AV1: blok_beton_km_2025 | AW1: aspal_km_2025 | AX1: lapen_km_2025 | AY1: baik_km_2025 | AZ1: sedang_km_2025 | BA1: rusak_ringan_km_2025 | BB1: rusak_berat_km_2025 | BC1: jalan_mantap_km_2025 | BD1: jalan_tidak_mantap_km_2025 | BE1: jalan_mantap_pct_2025 | BF1: jalan_tidak_mantap_pct_2025 | BG1: aadt_mc_2025 | BH1: sdi_baik_km_2025 | BI1: sdi_sedang_km_2025 | BJ1: sdi_rusak_ringan_km_2025 | BK1: sdi_rusak_berat_km_2025 | BL1: prior_handled_any_pre2024 | BM1: prior_handled_count_pre2024 | BN1: prior_handled_last_year_pre2024 | BO1: years_since_last_handled_pre2024 | BP1: prior_handled_any_pre2025 | BQ1: prior_handled_count_pre2025 | BR1: prior_handled_last_year_pre2025 | BS1: years_since_last_handled_pre2025 | BT1: prior_handled_any_pre2026 | BU1: prior_handled_count_pre2026 | BV1: prior_handled_last_year_pre2026 | BW1: years_since_last_handled_pre2026 | BX1: handled_any_2021 | BY1: handled_any_2022 | BZ1: handled_any_2023 | CA1: handled_any_2024 | CB1: handled_any_2025 | CC1: handled_pl_2021 | CD1: handled_pl_2022 | CE1: handled_pl_2023 | CF1: handled_pl_2024 | CG1: handled_pl_2025 | CH1: handled_tender_2021 | CI1: handled_tender_2022 | CJ1: handled_tender_2023 | CK1: handled_tender_2024 | CL1: handled_tender_2025 | CM1: planned_any_2026 | CN1: planned_any_2027 | CO1: planned_pl_2026 | CP1: planned_pl_2027 | CQ1: planned_tender_2026 | CR1: planned_tender_2027
A2: 1 | B2: 035 | C2: AES Nasution | D2: aes nasution | E2: Baluti | F2: Kandangan | G2: 1 | H2: 1 | I2: 1377 | J2: 0 | K2: 0 | L2: 714.1 | M2: 954.7 | N2: 1467.1 | O2: 166.2 | P2: 395.8 | Q2: 0 | R2: 0 | S2: 0 | T2: 0 | U2: 0 | V2: 0.24 | W2: 3.5 | X2: 0.24 | Y2: 0 | Z2: 0 | AA2: 0 | AB2: 0 | AC2: 0.24 | AD2: 0 | AE2: 0 | AF2: 0 | AG2: 1 | AH2: 0.24 | AI2: 3.5 | AJ2: 0.24 | AK2: 0 | AL2: 0 | AM2: 0 | AN2: 0 | AO2: 0.24 | AP2: 0 | AQ2: 0 | AR2: 0 | AS2: 1 | AT2: 0.24 | AU2: 0 | AV2: 0 | AW2: 0.23999999 | AX2: 0 | AY2: 0.23999999 | AZ2: 0 | BA2: 0 | BB2: 0 | BC2: 0.23999999 | BD2: 0 | BE2: 1 | BF2: 0 | BG2: 150 | BH2: 0.23999999 | BI2: 0 | BJ2: 0 | BK2: 0 | BL2: 0 | BM2: 0 | BP2: 1 | BQ2: 1 | BR2: 2024 | BS2: 1 | BT2: 1 | BU2: 1 | BV2: 2024 | BW2: 2 | BX2: 0 | BY2: 0 | BZ2: 0 | CA2: 1 | CB2: 0 | CC2: 0 | CD2: 0 | CE2: 0 | CF2: 0 | CG2: 0 | CH2: 0 | CI2: 0 | CJ2: 0 | CK2: 1 | CL2: 0 | CM2: 0 | CN2: 0 | CO2: 0 | CP2: 0 | CQ2: 0 | CR2: 0
A3: 2 | B3: 234 | C3: Air Miris - Ds. Wasah Hilir | D3: air miris – desa wasah hilir | E3: Wasah Hilir, Wasah Tengah | F3: Simpur | G3: 2 | H3: 1 | I3: 1294 | J3: 0 | K3: 1 | L3: 961.1 | M3: 2012.5 | N3: 5681 | O3: 667.2 | P3: 6453.8 | Q3: 0 | R3: 0 | S3: 0 | T3: 0 | U3: 0 | V3: 1.06 | W3: 3 | X3: 1.06 | Y3: 0 | Z3: 0 | AA3: 0 | AB3: 0 | AC3: 1.06 | AD3: 0 | AE3: 0 | AF3: 0 | AG3: 1 | AH3: 1.06 | AI3: 3 | AJ3: 1.06 | AK3: 0 | AL3: 0 | AM3: 0 | AN3: 0 | AO3: 1.06 | AP3: 0 | AQ3: 0 | AR3: 0 | AS3: 1 | AT3: 1.06 | AU3: 0 | AV3: 0 | AW3: 1.0599999 | AX3: 0 | AY3: 0.25999999 | AZ3: 0.80000001 | BA3: 0 | BB3: 0 | BC3: 1.06 | BD3: 0 | BE3: 1 | BF3: 0 | BG3: 150 | BH3: 0.25999999 | BI3: 0.80000001 | BJ3: 0 | BK3: 0 | BL3: 0 | BM3: 0 | BP3: 0 | BQ3: 0 | BT3: 0 | BU3: 0 | BX3: 0 | BY3: 0 | BZ3: 0 | CA3: 0 | CB3: 0 | CC3: 0 | CD3: 0 | CE3: 0 | CF3: 0 | CG3: 0 | CH3: 0 | CI3: 0 | CJ3: 0 | CK3: 0 | CL3: 0 | CM3: 0 | CN3: 0 | CO3: 0 | CP3: 0 | CQ3: 0 | CR3: 0
A4: 3 | B4: 345 | C4: Al - Ikhlas - Ds. Baluti | D4: al – ikhlas – desa baluti | E4: Baluti, Tibung Raya | F4: Kandangan | G4: 2 | H4: 1 | I4: 2315 | J4: 0 | K4: 0 | L4: 1257.5 | M4: 1407.6 | N4: 1286.8 | O4: 425.9 | P4: 1575.8 | Q4: 0 | R4: 0 | S4: 0 | T4: 0 | U4: 0 | V4: 0.38 | W4: 3.5 | X4: 0 | Y4: 0 | Z4: 0 | AA4: 0.38 | AB4: 0 | AC4: 0 | AD4: 0 | AE4: 0 | AF4: 0.38 | AG4: 0 | AH4: 0.38 | AI4: 3.5 | AJ4: 0.38 | AK4: 0 | AL4: 0 | AM4: 0 | AN4: 0 | AO4: 0.38 | AP4: 0 | AQ4: 0 | AR4: 0 | AS4: 1 | AT4: 0.38 | AU4: 0 | AV4: 0 | AW4: 0.38 | AX4: 0 | AY4: 0.38 | AZ4: 0 | BA4: 0 | BB4: 0 | BC4: 0.38 | BD4: 0 | BE4: 1 | BF4: 0 | BG4: 150 | BH4: 0.38 | BI4: 0 | BJ4: 0 | BK4: 0 | BL4: 0 | BM4: 0 | BP4: 1 | BQ4: 1 | BR4: 2024 | BS4: 1 | BT4: 1 | BU4: 1 | BV4: 2024 | BW4: 2 | BX4: 0 | BY4: 0 | BZ4: 0 | CA4: 1 | CB4: 0 | CC4: 0 | CD4: 0 | CE4: 0 | CF4: 0 | CG4: 0 | CH4: 0 | CI4: 0 | CJ4: 0 | CK4: 1 | CL4: 0 | CM4: 0 | CN4: 0 | CO4: 0 | CP4: 0 | CQ4: 0 | CR4: 0
A5: 4 | B5: 008 | C5: Aluh Idut | D5: aluh idut | E5: Kandangan Barat, Kandangan Kota, Kandangan Utara | F5: Kandangan | G5: 3 | H5: 1 | I5: 6205 | J5: 0 | K5: 1 | L5: 1109.5 | M5: 461.8 | N5: 2807.8 | O5: 138.8 | P5: 944.9 | Q5: 0 | R5: 0 | S5: 0 | T5: 0 | U5: 0 | V5: 1.34 | W5: 5 | X5: 1.34 | Y5: 0 | Z5: 0 | AA5: 0 | AB5: 0 | AC5: 1.34 | AD5: 0 | AE5: 0 | AF5: 0 | AG5: 1 | AH5: 1.34 | AI5: 5 | AJ5: 1.34 | AK5: 0 | AL5: 0 | AM5: 0 | AN5: 0 | AO5: 1.34 | AP5: 0 | AQ5: 0 | AR5: 0 | AS5: 1 | AT5: 1.34 | AU5: 0 | AV5: 0 | AW5: 1.34 | AX5: 0 | AY5: 0.5 | AZ5: 0.83999997 | BA5: 0 | BB5: 0 | BC5: 1.34 | BD5: 0 | BE5: 1 | BF5: 0 | BG5: 100 | BH5: 0.5 | BI5: 0.83999997 | BJ5: 0 | BK5: 0 | BL5: 0 | BM5: 0 | BP5: 0 | BQ5: 0 | BT5: 0 | BU5: 0 | BX5: 0 | BY5: 0 | BZ5: 0 | CA5: 0 | CB5: 0 | CC5: 0 | CD5: 0 | CE5: 0 | CF5: 0 | CG5: 0 | CH5: 0 | CI5: 0 | CJ5: 0 | CK5: 0 | CL5: 0 | CM5: 0 | CN5: 1 | CO5: 0 | CP5: 0 | CQ5: 0 | CR5: 1
A6: 5 | B6: 032 | C6: Amawang Kanan - Wasah Hulu | D6: amawang kanan – wasah hulu | E6: Amawang Kanan, Wasah Hulu | F6: Kandangan, Simpur | G6: 2 | H6: 2 | I6: 1122 | J6: 0 | K6: 1 | L6: 3281 | M6: 1687.3 | N6: 2540.2 | O6: 459.8 | P6: 3136 | Q6: 0 | R6: 0 | S6: 0 | T6: 0 | U6: 0 | V6: 3.17 | W6: 3.5 | X6: 3.17 | Y6: 0 | Z6: 0 | AA6: 0 | AB6: 0 | AC6: 3.17 | AD6: 0 | AE6: 0 | AF6: 0 | AG6: 1 | AH6: 3.17 | AI6: 3.5 | AJ6: 3.17 | AK6: 0 | AL6: 0 | AM6: 0 | AN6: 0 | AO6: 0 | AP6: 2.97 | AQ6: 0.2 | AR6: 0 | AS6: 0.93690852 | AT6: 3.17 | AU6: 0 | AV6: 0 | AW6: 3.1700001 | AX6: 0 | AY6: 0 | AZ6: 2.47 | BA6: 0.69999999 | BB6: 0 | BC6: 2.47 | BD6: 0.69999999 | BE6: 0.77917982 | BF6: 0.22082018 | BG6: 150 | BH6: 0 | BI6: 2.47 | BJ6: 0.69999999 | BK6: 0 | BL6: 1 | BM6: 1 | BN6: 2023 | BO6: 1 | BP6: 1 | BQ6: 1 | BR6: 2023 | BS6: 2 | BT6: 1 | BU6: 1 | BV6: 2023 | BW6: 3 | BX6: 0 | BY6: 0 | BZ6: 1 | CA6: 0 | CB6: 0 | CC6: 0 | CD6: 0 | CE6: 1 | CF6: 0 | CG6: 0 | CH6: 0 | CI6: 0 | CJ6: 0 | CK6: 0 | CL6: 0 | CM6: 0 | CN6: 0 | CO6: 0 | CP6: 0 | CQ6: 0 | CR6: 0
A7: 6 | B7: 031 | C7: Amawang Muka - Getek | D7: amawang muka – getek | E7: Amawang Kiri, Amawang Kiri Muka, Bariang, Sungai Paring | F7: Kandangan | G7: 4 | H7: 1 | I7: 2479 | J7: 0 | K7: 0 | L7: 4114.1 | M7: 3726.6 | N7: 5380 | O7: 191.1 | P7: 3795.8 | Q7: 0 | R7: 0 | S7: 0 | T7: 0 | U7: 0 | V7: 5.41 | W7: 3.5 | X7: 5.41 | Y7: 0 | Z7: 0 | AA7: 0 | AB7: 0 | AC7: 5.41 | AD7: 0 | AE7: 0 | AF7: 0 | AG7: 1 | AH7: 5.41 | AI7: 3.5 | AJ7: 5.41 | AK7: 0 | AL7: 0 | AM7: 0 | AN7: 0 | AO7: 4.6 | AP7: 0.41 | AQ7: 0.4 | AR7: 0 | AS7: 0.92606285 | AT7: 5.41 | AU7: 0 | AV7: 0 | AW7: 5.4099998 | AX7: 0 | AY7: 4.5 | AZ7: 0.41 | BA7: 0.5 | BB7: 0 | BC7: 4.91 | BD7: 0.5 | BE7: 0.90757856 | BF7: 0.092421442 | BG7: 150 | BH7: 4.5 | BI7: 0.41 | BJ7: 0.5 | BK7: 0 | BL7: 1 | BM7: 2 | BN7: 2023 | BO7: 1 | BP7: 1 | BQ7: 2 | BR7: 2023 | BS7: 2 | BT7: 1 | BU7: 3 | BV7: 2025 | BW7: 1 | BX7: 1 | BY7: 0 | BZ7: 1 | CA7: 0 | CB7: 1 | CC7: 1 | CD7: 0 | CE7: 1 | CF7: 0 | CG7: 1 | CH7: 0 | CI7: 0 | CJ7: 0 | CK7: 0 | CL7: 0 | CM7: 0 | CN7: 1 | CO7: 0 | CP7: 1 | CQ7: 0 | CR7: 0
A8: 7 | B8: 149 | C8: Ambarai - Madang | D8: ambarai – madang | E8: Karang Jawa, Madang | F8: Padang Batung | G8: 2 | H8: 1 | I8: 1088 | J8: 0 | K8: 0 | L8: 2381.2 | M8: 3220.9 | N8: 7125.8 | O8: 1028.5 | P8: 5524.6 | Q8: 0 | R8: 0 | S8: 0 | T8: 0 | U8: 0 | V8: 1.74 | W8: 3.5 | X8: 1.74 | Y8: 0 | Z8: 0 | AA8: 0 | AB8: 0 | AC8: 1.74 | AD8: 0 | AE8: 0 | AF8: 0 | AG8: 1 | AH8: 1.74 | AI8: 3.5 | AJ8: 1.74 | AK8: 0 | AL8: 0 | AM8: 0 | AN8: 0 | AO8: 1.74 | AP8: 0 | AQ8: 0 | AR8: 0 | AS8: 1 | AT8: 1.74 | AU8: 0 | AV8: 0 | AW8: 1.74 | AX8: 0 | AY8: 1.34 | AZ8: 0.40000001 | BA8: 0 | BB8: 0 | BC8: 1.74 | BD8: 0 | BE8: 1 | BF8: 0 | BG8: 150 | BH8: 1.34 | BI8: 0.40000001 | BJ8: 0 | BK8: 0 | BL8: 0 | BM8: 0 | BP8: 1 | BQ8: 1 | BR8: 2024 | BS8: 1 | BT8: 1 | BU8: 1 | BV8: 2024 | BW8: 2 | BX8: 0 | BY8: 0 | BZ8: 0 | CA8: 1 | CB8: 0 | CC8: 0 | CD8: 0 | CE8: 0 | CF8: 1 | CG8: 0 | CH8: 0 | CI8: 0 | CJ8: 0 | CK8: 0 | CL8: 0 | CM8: 1 | CN8: 0 | CO8: 1 | CP8: 0 | CQ8: 0 | CR8: 0
A9: 8 | B9: 187 | C9: AMD - Ds. Lok Binuang | D9: amd – desa lok binuang | E9: Lok Binuang, Telaga Langsat | F9: Telaga Langsat | G9: 2 | H9: 1 | I9: 763 | J9: 0 | K9: 0 | L9: 4179.5 | M9: 2818.2 | N9: 13938.7 | O9: 1329.4 | P9: 12075.8 | Q9: 0 | R9: 0 | S9: 0 | T9: 0 | U9: 0 | V9: 1.57 | W9: 3 | X9: 0.1 | Y9: 0 | Z9: 0 | AA9: 1.47 | AB9: 0 | AC9: 0 | AD9: 0 | AE9: 0 | AF9: 1.57 | AG9: 0 | AH9: 1.57 | AI9: 3.5 | AJ9: 0.2 | AK9: 0 | AL9: 0 | AM9: 1.37 | AN9: 0 | AO9: 0 | AP9: 0 | AQ9: 0 | AR9: 1.57 | AS9: 0 | AT9: 1.57 | AU9: 0 | AV9: 0 | AW9: 0.2 | AX9: 0 | AY9: 0 | AZ9: 0 | BA9: 0 | BB9: 0.2 | BC9: 0 | BD9: 0.2 | BE9: 0 | BF9: 1 | BG9: 150 | BH9: 0 | BI9: 0 | BJ9: 0 | BK9: 0.2 | BL9: 0 | BM9: 0 | BP9: 0 | BQ9: 0 | BT9: 0 | BU9: 0 | BX9: 0 | BY9: 0 | BZ9: 0 | CA9: 0 | CB9: 0 | CC9: 0 | CD9: 0 | CE9: 0 | CF9: 0 | CG9: 0 | CH9: 0 | CI9: 0 | CJ9: 0 | CK9: 0 | CL9: 0 | CM9: 0 | CN9: 1 | CO9: 0 | CP9: 0 | CQ9: 0 | CR9: 1
A10: 9 | B10: 214 | C10: Amparaya - Karangan - Hanau | D10: amparaya – karangan – hanau | E10: Amparaya, Panjampang Bahagia | F10: Simpur | G10: 2 | H10: 1 | I10: 1032 | J10: 0 | K10: 0 | L10: 4608.7 | M10: 5179.2 | N10: 10259.5 | O10: 1207.7 | P10: 10424.2 | Q10: 0 | R10: 0 | S10: 0 | T10: 0 | U10: 0 | V10: 4.36 | W10: 3.5 | X10: 4.36 | Y10: 0 | Z10: 0 | AA10: 0 | AB10: 0 | AC10: 0 | AD10: 4.16 | AE10: 0.2 | AF10: 0 | AG10: 0.95412844 | AH10: 4.36 | AI10: 3.5 | AJ10: 4.36 | AK10: 0 | AL10: 0 | AM10: 0 | AN10: 0 | AO10: 2.4 | AP10: 1.96 | AQ10: 0 | AR10: 0 | AS10: 1 | AT10: 4.36 | AU10: 0 | AV10: 0 | AW10: 4.3600001 | AX10: 0 | AY10: 2 | AZ10: 2.1600001 | BA10: 0.2 | BB10: 0 | BC10: 4.1600001 | BD10: 0.2 | BE10: 0.95412844 | BF10: 0.045871559 | BG10: 150 | BH10: 2 | BI10: 2.1600001 | BJ10: 0.2 | BK10: 0 | BL10: 1 | BM10: 3 | BN10: 2023 | BO10: 1 | BP10: 1 | BQ10: 3 | BR10: 2023 | BS10: 2 | BT10: 1 | BU10: 3 | BV10: 2023 | BW10: 3 | BX10: 1 | BY10: 1 | BZ10: 1 | CA10: 0 | CB10: 0 | CC10: 1 | CD10: 1 | CE10: 1 | CF10: 0 | CG10: 0 | CH10: 0 | CI10: 0 | CJ10: 0 | CK10: 0 | CL10: 0 | CM10: 0 | CN10: 0 | CO10: 0 | CP10: 0 | CQ10: 0 | CR10: 0
A11: 10 | B11: 011 | C11: Anggrek | D11: anggrek | E11: Kandangan Kota, Kandangan Utara | F11: Kandangan | G11: 2 | H11: 1 | I11: 4331 | J11: 0 | K11: 0 | L11: 781.6 | M11: 796.9 | N11: 2773.5 | O11: 196.3 | P11: 910.6 | Q11: 0 | R11: 0 | S11: 0 | T11: 0 | U11: 0 | V11: 0.23 | W11: 3 | X11: 0.23 | Y11: 0 | Z11: 0 | AA11: 0 | AB11: 0 | AC11: 0.23 | AD11: 0 | AE11: 0 | AF11: 0 | AG11: 1 | AH11: 0.23 | AI11: 3 | AJ11: 0.23 | AK11: 0 | AL11: 0 | AM11: 0 | AN11: 0 | AO11: 0.23 | AP11: 0 | AQ11: 0 | AR11: 0 | AS11: 1 | AT11: 0.23 | AU11: 0 | AV11: 0 | AW11: 0.23 | AX11: 0 | AY11: 0.23 | AZ11: 0 | BA11: 0 | BB11: 0 | BC11: 0.23 | BD11: 0 | BE11: 1 | BF11: 0 | BG11: 150 | BH11: 0.23 | BI11: 0 | BJ11: 0 | BK11: 0 | BL11: 1 | BM11: 1 | BN11: 2023 | BO11: 1 | BP11: 1 | BQ11: 1 | BR11: 2023 | BS11: 2 | BT11: 1 | BU11: 1 | BV11: 2023 | BW11: 3 | BX11: 0 | BY11: 0 | BZ11: 1 | CA11: 0 | CB11: 0 | CC11: 0 | CD11: 0 | CE11: 0 | CF11: 0 | CG11: 0 | CH11: 0 | CI11: 0 | CJ11: 1 | CK11: 0 | CL11: 0 | CM11: 0 | CN11: 0 | CO11: 0 | CP11: 0 | CQ11: 0 | CR11: 0
A12: 11 | B12: 346 | C12: Angkakai - Ds. Amawang Kiri | D12: angkakai – desa amawang kiri | E12: Amawang Kiri | F12: Kandangan | G12: 1 | H12: 1 | I12: 786 | J12: 0 | K12: 0 | L12: 4664.3 | M12: 3176.4 | N12: 5196.4 | O12: 490.7 | P12: 4346 | Q12: 0 | R12: 0 | S12: 0 | T12: 0 | U12: 0 | V12: 0.4 | W12: 3.5 | X12: 0 | Y12: 0 | Z12: 0 | AA12: 0.4 | AB12: 0 | AC12: 0 | AD12: 0 | AE12: 0 | AF12: 0.4 | AG12: 0 | AH12: 0.4 | AI12: 3.5 | AJ12: 0.4 | AK12: 0 | AL12: 0 | AM12: 0 | AN12: 0 | AO12: 0.4 | AP12: 0 | AQ12: 0 | AR12: 0 | AS12: 1 | AT12: 0.4 | AU12: 0 | AV12: 0 | AW12: 0.40000001 | AX12: 0 | AY12: 0.40000001 | AZ12: 0 | BA12: 0 | BB12: 0 | BC12: 0.40000001 | BD12: 0 | BE12: 1 | BF12: 0 | BG12: 150 | BH12: 0.40000001 | BI12: 0 | BJ12: 0 | BK12: 0 | BL12: 0 | BM12: 0 | BP12: 0 | BQ12: 0 | BT12: 0 | BU12: 0 | BX12: 0 | BY12: 0 | BZ12: 0 | CA12: 0 | CB12: 0 | CC12: 0 | CD12: 0 | CE12: 0 | CF12: 0 | CG12: 0 | CH12: 0 | CI12: 0 | CJ12: 0 | CK12: 0 | CL12: 0 | CM12: 0 | CN12: 0 | CO12: 0 | CP12: 0 | CQ12: 0 | CR12: 0
A13: 12 | B13: 178 | C13: Angkinang - Kayu Abang - Panggang Hijau | D13: angkinang – kayu abang – panggang hijau | E13: Angkinang, Kayu Abang, Tawia | F13: Angkinang | G13: 3 | H13: 1 | I13: 2516 | J13: 0 | K13: 1 | L13: 4170.6 | M13: 4803.9 | N13: 12260.5 | O13: 1030.9 | P13: 10397.6 | Q13: 0 | R13: 0 | S13: 0 | T13: 0 | U13: 0 | V13: 7 | W13: 3 | X13: 5.4 | Y13: 0 | Z13: 0 | AA13: 1.6 | AB13: 0 | AC13: 0 | AD13: 2.6 | AE13: 1.4 | AF13: 3 | AG13: 0.37142857 | AH13: 7 | AI13: 3 | AJ13: 5.4 | AK13: 0 | AL13: 0 | AM13: 0 | AN13: 1.6 | AO13: 1.6 | AP13: 1 | AQ13: 2.3 | AR13: 2.1 | AS13: 0.37142857 | AT13: 7 | AU13: 0 | AV13: 0 | AW13: 5.4000001 | AX13: 0 | AY13: 1.4 | AZ13: 1.1 | BA13: 1.3 | BB13: 1.6 | BC13: 2.5 | BD13: 2.9 | BE13: 0.46296297 | BF13: 0.53703703 | BG13: 150 | BH13: 1.4 | BI13: 1.1 | BJ13: 1.3 | BK13: 1.6 | BL13: 1 | BM13: 2 | BN13: 2023 | BO13: 1 | BP13: 1 | BQ13: 3 | BR13: 2024 | BS13: 1 | BT13: 1 | BU13: 3 | BV13: 2024 | BW13: 2 | BX13: 1 | BY13: 0 | BZ13: 1 | CA13: 1 | CB13: 0 | CC13: 1 | CD13: 0 | CE13: 1 | CF13: 1 | CG13: 0 | CH13: 0 | CI13: 0 | CJ13: 0 | CK13: 0 | CL13: 0 | CM13: 0 | CN13: 0 | CO13: 0 | CP13: 0 | CQ13: 0 | CR13: 0
A14: 13 | B14: 175 | C14: Angkinang - Telaga Langsat | D14: angkinang – telaga langsat | E14: Angkinang, Angkinang Selatan, Lok Binuang, Mandala, Telaga Langsat | F14: Angkinang, Telaga Langsat | G14: 5 | H14: 2 | I14: 2430 | J14: 0 | K14: 1 | L14: 2807.7 | M14: 2660.1 | N14: 12566.9 | O14: 42.4 | P14: 10704 | Q14: 0 | R14: 0 | S14: 0 | T14: 0 | U14: 0 | V14: 5.58 | W14: 3 | X14: 5.58 | Y14: 0 | Z14: 0 | AA14: 0 | AB14: 0 | AC14: 0 | AD14: 3.78 | AE14: 1.8 | AF14: 0 | AG14: 0.67741935 | AH14: 5.58 | AI14: 3 | AJ14: 5.58 | AK14: 0 | AL14: 0 | AM14: 0 | AN14: 0 | AO14: 4.38 | AP14: 0.6 | AQ14: 0.6 | AR14: 0 | AS14: 0.89247312 | AT14: 5.58 | AU14: 0 | AV14: 0 | AW14: 5.5799999 | AX14: 0 | AY14: 0.40000001 | AZ14: 3.98 | BA14: 1.2 | BB14: 0 | BC14: 4.38 | BD14: 1.2 | BE14: 0.78494623 | BF14: 0.21505377 | BG14: 150 | BH14: 0.40000001 | BI14: 3.98 | BJ14: 1.2 | BK14: 0 | BL14: 1 | BM14: 1 | BN14: 2021 | BO14: 3 | BP14: 1 | BQ14: 2 | BR14: 2024 | BS14: 1 | BT14: 1 | BU14: 3 | BV14: 2025 | BW14: 1 | BX14: 1 | BY14: 0 | BZ14: 0 | CA14: 1 | CB14: 1 | CC14: 0 | CD14: 0 | CE14: 0 | CF14: 1 | CG14: 1 | CH14: 1 | CI14: 0 | CJ14: 0 | CK14: 1 | CL14: 0 | CM14: 0 | CN14: 0 | CO14: 0 | CP14: 0 | CQ14: 0 | CR14: 0
A15: 14 | B15: 172 | C15: Angkinang Selatan - Tawia - Wawaran | D15: angkinang selatan – tawia – wawaran | E15: Angkinang Selatan, Bakarung, Taniran Kubah, Tawia | F15: Angkinang | G15: 4 | H15: 1 | I15: 3114 | J15: 0 | K15: 0 | L15: 3473.9 | M15: 4541 | N15: 11563.7 | O15: 1798.1 | P15: 9700.8 | Q15: 0 | R15: 0 | S15: 0 | T15: 0 | U15: 0 | V15: 5.88 | W15: 3 | X15: 5.88 | Y15: 0 | Z15: 0 | AA15: 0 | AB15: 0 | AC15: 0 | AD15: 4.48 | AE15: 1.4 | AF15: 0 | AG15: 0.76190476 | AH15: 5.88 | AI15: 3 | AJ15: 5.88 | AK15: 0 | AL15: 0 | AM15: 0 | AN15: 0 | AO15: 1.8 | AP15: 3 | AQ15: 1.08 | AR15: 0 | AS15: 0.81632653 | AT15: 5.88 | AU15: 0 | AV15: 0 | AW15: 5.8800001 | AX15: 0 | AY15: 1.7 | AZ15: 3.28 | BA15: 0.89999998 | BB15: 0 | BC15: 4.98 | BD15: 0.89999998 | BE15: 0.84693878 | BF15: 0.15306122 | BG15: 150 | BH15: 1.7 | BI15: 3.28 | BJ15: 0.89999998 | BK15: 0 | BL15: 1 | BM15: 1 | BN15: 2023 | BO15: 1 | BP15: 1 | BQ15: 2 | BR15: 2024 | BS15: 1 | BT15: 1 | BU15: 2 | BV15: 2024 | BW15: 2 | BX15: 0 | BY15: 0 | BZ15: 1 | CA15: 1 | CB15: 0 | CC15: 0 | CD15: 0 | CE15: 1 | CF15: 0 | CG15: 0 | CH15: 0 | CI15: 0 | CJ15: 0 | CK15: 1 | CL15: 0 | CM15: 1 | CN15: 0 | CO15: 0 | CP15: 0 | CQ15: 1 | CR15: 1
A16: 15 | B16: 347 | C16: Anjiran Rantauan - Ds. Taniran Tengah | D16: anjiran rantauan – desa taniran tengah | E16: Taniran Selatan | F16: Angkinang | G16: 1 | H16: 1 | I16: 545 | J16: 0 | K16: 1 | L16: 2869.7 | M16: 3143.5 | N16: 8536.5 | O16: 474.2 | P16: 6673.6 | Q16: 0 | R16: 0 | S16: 0 | T16: 0 | U16: 0 | V16: 1.21 | W16: 3.5 | X16: 1.21 | Y16: 0 | Z16: 0 | AA16: 0 | AB16: 0 | AC16: 0 | AD16: 0 | AE16: 0 | AF16: 1.21 | AG16: 0 | AH16: 1.21 | AI16: 3.5 | AJ16: 1.21 | AK16: 0 | AL16: 0 | AM16: 0 | AN16: 0 | AO16: 0 | AP16: 0 | AQ16: 0 | AR16: 1.21 | AS16: 0 | AT16: 1.21 | AU16: 0 | AV16: 0 | AW16: 0.70999998 | AX16: 0 | AY16: 0 | AZ16: 0 | BA16: 0 | BB16: 0.70999998 | BC16: 0 | BD16: 0.70999998 | BE16: 0 | BF16: 1 | BG16: 150 | BH16: 0 | BI16: 0 | BJ16: 0 | BK16: 0.70999998 | BL16: 0 | BM16: 0 | BP16: 0 | BQ16: 0 | BT16: 0 | BU16: 0 | BX16: 0 | BY16: 0 | BZ16: 0 | CA16: 0 | CB16: 0 | CC16: 0 | CD16: 0 | CE16: 0 | CF16: 0 | CG16: 0 | CH16: 0 | CI16: 0 | CJ16: 0 | CK16: 0 | CL16: 0 | CM16: 0 | CN16: 1 | CO16: 0 | CP16: 0 | CQ16: 0 | CR16: 1
A17: 16 | B17: 097 | C17: Asam Cangkuk - Telaga Bidadari | D17: asam cangkuk – telaga bidadari | E17: Amawang Kanan, Telaga Bidadari, Wasah Hulu | F17: Kandangan, Simpur, Sungai Raya | G17: 3 | H17: 3 | I17: 1790 | J17: 0 | K17: 0 | L17: 2965.8 | M17: 2977.4 | N17: 2083.4 | O17: 862.4 | P17: 3010.9 | Q17: 0 | R17: 0 | S17: 0 | T17: 0 | U17: 0 | V17: 0.83 | W17: 2 | X17: 0.83 | Y17: 0 | Z17: 0 | AA17: 0 | AB17: 0 | AC17: 0 | AD17: 0 | AE17: 0 | AF17: 0.83 | AG17: 0 | AH17: 0.83 | AI17: 2 | AJ17: 0.83 | AK17: 0 | AL17: 0 | AM17: 0 | AN17: 0 | AO17: 0 | AP17: 0 | AQ17: 0 | AR17: 0.83 | AS17: 0 | AT17: 0.83 | AU17: 0 | AV17: 0 | AW17: 0.82999998 | AX17: 0 | AY17: 0 | AZ17: 0 | BA17: 0 | BB17: 0.82999998 | BC17: 0 | BD17: 0.82999998 | BE17: 0 | BF17: 1 | BG17: 150 | BH17: 0 | BI17: 0 | BJ17: 0 | BK17: 0.82999998 | BL17: 0 | BM17: 0 | BP17: 0 | BQ17: 0 | BT17: 0 | BU17: 0 | BX17: 0 | BY17: 0 | BZ17: 0 | CA17: 0 | CB17: 0 | CC17: 0 | CD17: 0 | CE17: 0 | CF17: 0 | CG17: 0 | CH17: 0 | CI17: 0 | CJ17: 0 | CK17: 0 | CL17: 0 | CM17: 0 | CN17: 0 | CO17: 0 | CP17: 0 | CQ17: 0 | CR17: 0
A18: 17 | B18: 348 | C18: Asam Duhat - Ds. Pantai Ulin | D18: asam duhat – desa pantai ulin | E18: Pantai Ulin | F18: Simpur | G18: 1 | H18: 1 | I18: 708 | J18: 0 | K18: 0 | L18: 4362.9 | M18: 4148.6 | N18: 11085.9 | O18: 532.9 | P18: 7234.7 | Q18: 0 | R18: 0 | S18: 0 | T18: 0 | U18: 0 | V18: 1.11 | W18: 3.5 | X18: 0 | Y18: 0 | Z18: 0 | AA18: 1.11 | AB18: 0 | AC18: 0 | AD18: 0 | AE18: 0 | AF18: 1.11 | AG18: 0 | AH18: 1.11 | AI18: 3.5 | AJ18: 0 | AK18: 0 | AL18: 0 | AM18: 1.11 | AN18: 0 | AO18: 0 | AP18: 0 | AQ18: 0 | AR18: 1.11 | AS18: 0 | AT18: 1.11 | AU18: 0 | AV18: 0 | AW18: 0 | AX18: 0 | AY18: 0 | AZ18: 0 | BA18: 0 | BB18: 0 | BC18: 0 | BD18: 0 | BE18: 0 | BF18: 0 | BG18: 150 | BH18: 0 | BI18: 0 | BJ18: 0 | BK18: 0 | BL18: 1 | BM18: 2 | BN18: 2023 | BO18: 1 | BP18: 1 | BQ18: 2 | BR18: 2023 | BS18: 2 | BT18: 1 | BU18: 2 | BV18: 2023 | BW18: 3 | BX18: 0 | BY18: 1 | BZ18: 1 | CA18: 0 | CB18: 0 | CC18: 0 | CD18: 1 | CE18: 1 | CF18: 0 | CG18: 0 | CH18: 0 | CI18: 0 | CJ18: 0 | CK18: 0 | CL18: 0 | CM18: 1 | CN18: 0 | CO18: 0 | CP18: 0 | CQ18: 1 | CR18: 0
A19: 18 | B19: 123 | C19: Asam Seranggan - Asam Tamiyang | D19: asam seranggan – asam tamiyang | E19: Asam, Tamiyang | F19: Sungai Raya | G19: 2 | H19: 1 | I19: 797 | J19: 0 | K19: 0 | L19: 7415 | M19: 4953 | N19: 8268.7 | O19: 979.8 | P19: 12484.5 | Q19: 0 | R19: 0 | S19: 0 | T19: 0 | U19: 0 | V19: 1.02 | W19: 3 | X19: 0 | Y19: 0 | Z19: 0 | AA19: 1.02 | AB19: 0 | AC19: 0 | AD19: 0 | AE19: 0 | AF19: 1.02 | AG19: 0 | AH19: 1.02 | AI19: 3 | AJ19: 0 | AK19: 0 | AL19: 0 | AM19: 1.02 | AN19: 0 | AO19: 0 | AP19: 0 | AQ19: 0 | AR19: 1.02 | AS19: 0 | AT19: 1.02 | AU19: 1.02 | AV19: 0 | AW19: 0 | AX19: 0 | AY19: 1.02 | AZ19: 0 | BA19: 0 | BB19: 0 | BC19: 1.02 | BD19: 0 | BE19: 1 | BF19: 0 | BG19: 150 | BH19: 0 | BI19: 0 | BJ19: 0 | BK19: 0 | BL19: 1 | BM19: 1 | BN19: 2022 | BO19: 2 | BP19: 1 | BQ19: 1 | BR19: 2022 | BS19: 3 | BT19: 1 | BU19: 1 | BV19: 2022 | BW19: 4 | BX19: 0 | BY19: 1 | BZ19: 0 | CA19: 0 | CB19: 0 | CC19: 0 | CD19: 1 | CE19: 0 | CF19: 0 | CG19: 0 | CH19: 0 | CI19: 0 | CJ19: 0 | CK19: 0 | CL19: 0 | CM19: 0 | CN19: 0 | CO19: 0 | CP19: 0 | CQ19: 0 | CR19: 0
A20: 19 | B20: 238 | C20: At-Taubah - Ds. Kapuh | D20: at – taubah – desa kapuh | E20: Kapuh | F20: Simpur | G20: 1 | H20: 1 | I20: 682 | J20: 0 | K20: 0 | L20: 2565.8 | M20: 3045 | N20: 3705.6 | O20: 527.9 | P20: 5104.2 | Q20: 0 | R20: 0 | S20: 0 | T20: 0 | U20: 0 | V20: 0.47 | W20: 3 | X20: 0.47 | Y20: 0 | Z20: 0 | AA20: 0 | AB20: 0 | AC20: 0.47 | AD20: 0 | AE20: 0 | AF20: 0 | AG20: 1 | AH20: 0.47 | AI20: 3 | AJ20: 0.47 | AK20: 0 | AL20: 0 | AM20: 0 | AN20: 0 | AO20: 0.47 | AP20: 0 | AQ20: 0 | AR20: 0 | AS20: 1 | AT20: 0.47 | AU20: 0 | AV20: 0 | AW20: 0.47 | AX20: 0 | AY20: 0.1 | AZ20: 0.37 | BA20: 0 | BB20: 0 | BC20: 0.47000001 | BD20: 0 | BE20: 1 | BF20: 0 | BG20: 150 | BH20: 0.1 | BI20: 0.37 | BJ20: 0 | BK20: 0 | BL20: 0 | BM20: 0 | BP20: 0 | BQ20: 0 | BT20: 0 | BU20: 0 | BX20: 0 | BY20: 0 | BZ20: 0 | CA20: 0 | CB20: 0 | CC20: 0 | CD20: 0 | CE20: 0 | CF20: 0 | CG20: 0 | CH20: 0 | CI20: 0 | CJ20: 0 | CK20: 0 | CL20: 0 | CM20: 0 | CN20: 0 | CO20: 0 | CP20: 0 | CQ20: 0 | CR20: 0
A21: 20 | B21: 343 | C21: Badaun - Ds. Bjayau Lama | D21: badaun – desa bjayau lama | E21: Bajayau Lama | F21: Daha Barat | G21: 1 | H21: 1 | I21: 426 | J21: 0 | K21: 0 | O21: 612 | Q21: 1 | R21: 1 | S21: 1 | T21: 1 | U21: 0 | V21: 3.1 | W21: 3 | X21: 0 | Y21: 0 | Z21: 0 | AA21: 0 | AB21: 3.1 | AC21: 0 | AD21: 0 | AE21: 0 | AF21: 3.1 | AG21: 0 | AH21: 3.1 | AI21: 3 | AJ21: 0 | AK21: 0 | AL21: 0 | AM21: 0 | AN21: 3.1 | AO21: 0 | AP21: 0 | AQ21: 0 | AR21: 3.1 | AS21: 0 | AT21: 3.1 | AU21: 0 | AV21: 0 | AW21: 0 | AX21: 0 | AY21: 0 | AZ21: 0 | BA21: 0 | BB21: 0 | BC21: 0 | BD21: 0 | BE21: 0 | BF21: 0 | BG21: 150 | BH21: 0 | BI21: 0 | BJ21: 0 | BK21: 0 | BL21: 0 | BM21: 0 | BP21: 0 | BQ21: 0 | BT21: 0 | BU21: 0 | BX21: 0 | BY21: 0 | BZ21: 0 | CA21: 0 | CB21: 0 | CC21: 0 | CD21: 0 | CE21: 0 | CF21: 0 | CG21: 0 | CH21: 0 | CI21: 0 | CJ21: 0 | CK21: 0 | CL21: 0 | CM21: 0 | CN21: 0 | CO21: 0 | CP21: 0 | CQ21: 0 | CR21: 0
A22: 21 | B22: 249 | C22: Bago Tanggul - Katilang - Teratai | D22: bago tanggul – katilang – teratai | E22: Bago Tanggul, Balanti, Kalumpang, Karang Bulan | F22: Kalumpang | G22: 4 | H22: 1 | I22: 960 | J22: 0 | K22: 0 | L22: 10210.5 | M22: 7816.6 | N22: 20724.2 | O22: 161.6 | P22: 22103.7 | Q22: 0 | R22: 0 | S22: 0 | T22: 0 | U22: 0 | V22: 9.71 | W22: 4 | X22: 7.3 | Y22: 0 | Z22: 0 | AA22: 0 | AB22: 2.41 | AC22: 7.3 | AD22: 0 | AE22: 0 | AF22: 2.41 | AG22: 0.75180227 | AH22: 9.71 | AI22: 4 | AJ22: 7.3 | AK22: 0 | AL22: 0 | AM22: 0 | AN22: 2.41 | AO22: 6.2 | AP22: 1 | AQ22: 0.1 | AR22: 2.41 | AS22: 0.7415036 | AT22: 9.71 | AU22: 0 | AV22: 0 | AW22: 7.3000002 | AX22: 0 | AY22: 6.5999999 | AZ22: 0.69999999 | BA22: 0 | BB22: 0 | BC22: 7.2999999 | BD22: 0 | BE22: 1 | BF22: 0 | BG22: 150 | BH22: 6.5999999 | BI22: 0.69999999 | BJ22: 0 | BK22: 0 | BL22: 1 | BM22: 1 | BN22: 2022 | BO22: 2 | BP22: 1 | BQ22: 1 | BR22: 2022 | BS22: 3 | BT22: 1 | BU22: 1 | BV22: 2022 | BW22: 4 | BX22: 0 | BY22: 1 | BZ22: 0 | CA22: 0 | CB22: 0 | CC22: 0 | CD22: 0 | CE22: 0 | CF22: 0 | CG22: 0 | CH22: 0 | CI22: 1 | CJ22: 0 | CK22: 0 | CL22: 0 | CM22: 0 | CN22: 0 | CO22: 0 | CP22: 0 | CQ22: 0 | CR22: 0
A23: 22 | B23: 069 | C23: Baiturrahim Parincahan | D23: baiturrahim parincahan | E23: Kandangan Barat | F23: Kandangan | G23: 1 | H23: 1 | I23: 1874 | J23: 0 | K23: 1 | L23: 2675.7 | M23: 2608.4 | N23: 4437.4 | O23: 935.9 | P23: 2574.5 | Q23: 0 | R23: 0 | S23: 0 | T23: 0 | U23: 0 | V23: 1.42 | W23: 3 | X23: 1.2 | Y23: 0 | Z23: 0 | AA23: 0 | AB23: 0.22 | AC23: 0.4 | AD23: 0 | AE23: 0.8 | AF23: 0.22 | AG23: 0.28169014 | AH23: 1.42 | AI23: 3 | AJ23: 1.2 | AK23: 0 | AL23: 0 | AM23: 0.22 | AN23: 0 | AO23: 0 | AP23: 0.4 | AQ23: 0.8 | AR23: 0.22 | AS23: 0.28169014 | AT23: 1.42 | AU23: 0 | AV23: 0 | AW23: 1.2 | AX23: 0 | AY23: 0 | AZ23: 0.30000001 | BA23: 0.30000001 | BB23: 0.60000002 | BC23: 0.30000001 | BD23: 0.90000004 | BE23: 0.25 | BF23: 0.75 | BG23: 150 | BH23: 0 | BI23: 0.30000001 | BJ23: 0.30000001 | BK23: 0.60000002 | BL23: 1 | BM23: 1 | BN23: 2023 | BO23: 1 | BP23: 1 | BQ23: 1 | BR23: 2023 | BS23: 2 | BT23: 1 | BU23: 2 | BV23: 2025 | BW23: 1 | BX23: 0 | BY23: 0 | BZ23: 1 | CA23: 0 | CB23: 1 | CC23: 0 | CD23: 0 | CE23: 1 | CF23: 0 | CG23: 1 | CH23: 0 | CI23: 0 | CJ23: 0 | CK23: 0 | CL23: 0 | CM23: 0 | CN23: 0 | CO23: 0 | CP23: 0 | CQ23: 0 | CR23: 0
A24: 23 | B24: 340 | C24: Bajayau - Ds. Bajayau Tengah | D24: bajayau – desa bajayau tengah | E24: Bajayau, Bajayau Tengah | F24: Daha Barat | G24: 2 | H24: 1 | I24: 734 | J24: 0 | K24: 0 | L24: 3635.1 | M24: 1570.2 | N24: 17922.5 | O24: 1051.1 | Q24: 1 | R24: 0 | S24: 0 | T24: 0 | U24: 0 | V24: 7.58 | W24: 3.5 | X24: 3.1 | Y24: 0 | Z24: 0 | AA24: 0.1 | AB24: 4.38 | AC24: 3.1 | AD24: 0 | AE24: 0 | AF24: 4.48 | AG24: 0.40897098 | AH24: 7.58 | AI24: 3.5 | AJ24: 2.8 | AK24: 0 | AL24: 0 | AM24: 0.4 | AN24: 4.38 | AO24: 2.4 | AP24: 0 | AQ24: 0.2 | AR24: 4.98 | AS24: 0.31662269 | AT24: 7.58 | AU24: 0 | AV24: 0 | AW24: 3 | AX24: 0 | AY24: 2.0999999 | AZ24: 0.40000001 | BA24: 0.1 | BB24: 0.40000001 | BC24: 2.4999999 | BD24: 0.50000001 | BE24: 0.83333333 | BF24: 0.16666667 | BG24: 150 | BH24: 2.0999999 | BI24: 0.40000001 | BJ24: 0.1 | BK24: 0.40000001 | BL24: 1 | BM24: 1 | BN24: 2023 | BO24: 1 | BP24: 1 | BQ24: 1 | BR24: 2023 | BS24: 2 | BT24: 1 | BU24: 2 | BV24: 2025 | BW24: 1 | BX24: 0 | BY24: 0 | BZ24: 1 | CA24: 0 | CB24: 1 | CC24: 0 | CD24: 0 | CE24: 0 | CF24: 0 | CG24: 0 | CH24: 0 | CI24: 0 | CJ24: 1 | CK24: 0 | CL24: 1 | CM24: 1 | CN24: 0 | CO24: 0 | CP24: 0 | CQ24: 1 | CR24: 0
A25: 24 | B25: 167 | C25: Bakarung - Rantauan | D25: bakarung – rantauan | E25: Bakarung, Gambah Dalam Barat, Gambah Luar, Taniran Selatan | F25: Angkinang, Kandangan | G25: 4 | H25: 2 | I25: 2506 | J25: 1 | K25: 1 | L25: 1752.4 | M25: 2792.8 | N25: 8362.7 | O25: 1550.7 | P25: 6499.8 | Q25: 0 | R25: 0 | S25: 0 | T25: 0 | U25: 0 | V25: 3.03 | W25: 3.5 | X25: 3.03 | Y25: 0 | Z25: 0 | AA25: 0 | AB25: 0 | AC25: 3.03 | AD25: 0 | AE25: 0 | AF25: 0 | AG25: 1 | AH25: 3.03 | AI25: 3.5 | AJ25: 3.03 | AK25: 0 | AL25: 0 | AM25: 0 | AN25: 0 | AO25: 3.03 | AP25: 0 | AQ25: 0 | AR25: 0 | AS25: 1 | AT25: 3.03 | AU25: 0 | AV25: 0 | AW25: 3.03 | AX25: 0 | AY25: 1 | AZ25: 1.13 | BA25: 0.89999998 | BB25: 0 | BC25: 2.13 | BD25: 0.89999998 | BE25: 0.7029703 | BF25: 0.2970297 | BG25: 150 | BH25: 1 | BI25: 1.13 | BJ25: 0.89999998 | BK25: 0 | BL25: 1 | BM25: 2 | BN25: 2023 | BO25: 1 | BP25: 1 | BQ25: 2 | BR25: 2023 | BS25: 2 | BT25: 1 | BU25: 2 | BV25: 2023 | BW25: 3 | BX25: 0 | BY25: 1 | BZ25: 1 | CA25: 0 | CB25: 0 | CC25: 0 | CD25: 0 | CE25: 0 | CF25: 0 | CG25: 0 | CH25: 0 | CI25: 1 | CJ25: 1 | CK25: 0 | CL25: 0 | CM25: 0 | CN25: 0 | CO25: 0 | CP25: 0 | CQ25: 0 | CR25: 0
A26: 25 | B26: 179 | C26: Bakarung -Tabihi - Karang Jawa | D26: bakarung – tabihi – karang jawa | E26: Bakarung, Karang Jawa, Karang Jawa Muka, Tabihi | F26: Angkinang, Padang Batung | G26: 4 | H26: 2 | I26: 2766 | J26: 0 | K26: 1 | L26: 2678.7 | M26: 1551.4 | N26: 5058.9 | O26: 419.1 | P26: 3325.5 | Q26: 0 | R26: 0 | S26: 0 | T26: 0 | U26: 0 | V26: 4.57 | W26: 3.5 | X26: 4.57 | Y26: 0 | Z26: 0 | AA26: 0 | AB26: 0 | AC26: 0 | AD26: 4.57 | AE26: 0 | AF26: 0 | AG26: 1 | AH26: 4.57 | AI26: 3.5 | AJ26: 4.57 | AK26: 0 | AL26: 0 | AM26: 0 | AN26: 0 | AO26: 0 | AP26: 4.57 | AQ26: 0 | AR26: 0 | AS26: 1 | AT26: 4.57 | AU26: 0 | AV26: 0 | AW26: 4.5700002 | AX26: 0 | AY26: 0 | AZ26: 2.5699999 | BA26: 2 | BB26: 0 | BC26: 2.5699999 | BD26: 2 | BE26: 0.56236323 | BF26: 0.43763677 | BG26: 150 | BH26: 0 | BI26: 2.5699999 | BJ26: 2 | BK26: 0 | BL26: 1 | BM26: 1 | BN26: 2023 | BO26: 1 | BP26: 1 | BQ26: 1 | BR26: 2023 | BS26: 2 | BT26: 1 | BU26: 2 | BV26: 2025 | BW26: 1 | BX26: 0 | BY26: 0 | BZ26: 1 | CA26: 0 | CB26: 1 | CC26: 0 | CD26: 0 | CE26: 0 | CF26: 0 | CG26: 0 | CH26: 0 | CI26: 0 | CJ26: 1 | CK26: 0 | CL26: 1 | CM26: 1 | CN26: 0 | CO26: 0 | CP26: 0 | CQ26: 1 | CR26: 0
A27: 26 | B27: 056 | C27: Bakarung Tengah - Karang Jawa | D27: bakarung tengah – karang jawa | E27: Gambah Luar, Gambah Luar Muka, Karang Jawa Muka | F27: Kandangan, Padang Batung | G27: 3 | H27: 2 | I27: 1780 | J27: 0 | K27: 1 | L27: 2368.5 | M27: 1835.5 | N27: 4559.7 | O27: 89.1 | P27: 2826.2 | Q27: 0 | R27: 0 | S27: 0 | T27: 0 | U27: 0 | V27: 3.77 | W27: 3.5 | X27: 3.77 | Y27: 0 | Z27: 0 | AA27: 0 | AB27: 0 | AC27: 3.77 | AD27: 0 | AE27: 0 | AF27: 0 | AG27: 1 | AH27: 3.77 | AI27: 3.5 | AJ27: 3.77 | AK27: 0 | AL27: 0 | AM27: 0 | AN27: 0 | AO27: 0 | AP27: 3.77 | AQ27: 0 | AR27: 0 | AS27: 1 | AT27: 3.77 | AU27: 0 | AV27: 0 | AW27: 3.77 | AX27: 0 | AY27: 0 | AZ27: 3.0699999 | BA27: 0.69999999 | BB27: 0 | BC27: 3.0699999 | BD27: 0.69999999 | BE27: 0.81432361 | BF27: 0.18567639 | BG27: 150 | BH27: 0 | BI27: 3.0699999 | BJ27: 0.69999999 | BK27: 0 | BL27: 1 | BM27: 3 | BN27: 2023 | BO27: 1 | BP27: 1 | BQ27: 3 | BR27: 2023 | BS27: 2 | BT27: 1 | BU27: 3 | BV27: 2023 | BW27: 3 | BX27: 1 | BY27: 1 | BZ27: 1 | CA27: 0 | CB27: 0 | CC27: 1 | CD27: 1 | CE27: 1 | CF27: 0 | CG27: 0 | CH27: 0 | CI27: 0 | CJ27: 0 | CK27: 0 | CL27: 0 | CM27: 0 | CN27: 0 | CO27: 0 | CP27: 0 | CQ27: 0 | CR27: 0
A28: 27 | B28: 219 | C28: Balaimas - Hanau | D28: balaimas – hanau | E28: Panjampang Bahagia, Pantai Ulin | F28: Simpur | G28: 2 | H28: 1 | I28: 1150 | J28: 0 | K28: 0 | L28: 6620.7 | M28: 4762 | N28: 8803.8 | O28: 1614.2 | P28: 8968.5 | Q28: 0 | R28: 0 | S28: 0 | T28: 0 | U28: 0 | V28: 2.33 | W28: 3.5 | X28: 2.33 | Y28: 0 | Z28: 0 | AA28: 0 | AB28: 0 | AC28: 2.33 | AD28: 0 | AE28: 0 | AF28: 0 | AG28: 1 | AH28: 2.33 | AI28: 3.5 | AJ28: 2.33 | AK28: 0 | AL28: 0 | AM28: 0 | AN28: 0 | AO28: 2.33 | AP28: 0 | AQ28: 0 | AR28: 0 | AS28: 1 | AT28: 2.33 | AU28: 0 | AV28: 0 | AW28: 2.3299999 | AX28: 0 | AY28: 0 | AZ28: 2.3299999 | BA28: 0 | BB28: 0 | BC28: 2.3299999 | BD28: 0 | BE28: 1 | BF28: 0 | BG28: 150 | BH28: 0 | BI28: 2.3299999 | BJ28: 0 | BK28: 0 | BL28: 1 | BM28: 2 | BN28: 2023 | BO28: 1 | BP28: 1 | BQ28: 2 | BR28: 2023 | BS28: 2 | BT28: 1 | BU28: 2 | BV28: 2023 | BW28: 3 | BX28: 1 | BY28: 0 | BZ28: 1 | CA28: 0 | CB28: 0 | CC28: 1 | CD28: 0 | CE28: 1 | CF28: 0 | CG28: 0 | CH28: 0 | CI28: 0 | CJ28: 0 | CK28: 0 | CL28: 0 | CM28: 0 | CN28: 0 | CO28: 0 | CP28: 0 | CQ28: 0 | CR28: 0
A29: 28 | B29: 251 | C29: Balanti - (Ex. P3DT) | D29: balanti – p3dt | E29: Balanti, Karang Bulan | F29: Kalumpang | G29: 2 | H29: 1 | I29: 426 | J29: 0 | K29: 0 | L29: 4304.7 | M29: 1910.8 | N29: 14818.3 | O29: 1026 | P29: 16197.8 | Q29: 0 | R29: 0 | S29: 0 | T29: 0 | U29: 0 | V29: 1.66 | W29: 3 | X29: 1.66 | Y29: 0 | Z29: 0 | AA29: 0 | AB29: 0 | AC29: 1.66 | AD29: 0 | AE29: 0 | AF29: 0 | AG29: 1 | AH29: 1.66 | AI29: 3 | AJ29: 1.66 | AK29: 0 | AL29: 0 | AM29: 0 | AN29: 0 | AO29: 1.66 | AP29: 0 | AQ29: 0 | AR29: 0 | AS29: 1 | AT29: 1.66 | AU29: 0 | AV29: 0 | AW29: 1.66 | AX29: 0 | AY29: 1.0599999 | AZ29: 0.60000002 | BA29: 0 | BB29: 0 | BC29: 1.66 | BD29: 0 | BE29: 1 | BF29: 0 | BG29: 150 | BH29: 1.0599999 | BI29: 0.60000002 | BJ29: 0 | BK29: 0 | BL29: 1 | BM29: 1 | BN29: 2022 | BO29: 2 | BP29: 1 | BQ29: 1 | BR29: 2022 | BS29: 3 | BT29: 1 | BU29: 1 | BV29: 2022 | BW29: 4 | BX29: 0 | BY29: 1 | BZ29: 0 | CA29: 0 | CB29: 0 | CC29: 0 | CD29: 1 | CE29: 0 | CF29: 0 | CG29: 0 | CH29: 0 | CI29: 0 | CJ29: 0 | CK29: 0 | CL29: 0 | CM29: 0 | CN29: 0 | CO29: 0 | CP29: 0 | CQ29: 0 | CR29: 0
A30: 29 | B30: 256 | C30: Balimau - Murung Dalam | D30: balimau – murung dalam | E30: Balimau | F30: Kalumpang | G30: 1 | H30: 1 | I30: 310 | J30: 0 | K30: 0 | L30: 8506.9 | M30: 6113.1 | N30: 19020.6 | O30: 1650.5 | P30: 20400.1 | Q30: 0 | R30: 0 | S30: 0 | T30: 0 | U30: 0 | V30: 1.46 | W30: 2.5 | X30: 0 | Y30: 0 | Z30: 0 | AA30: 0 | AB30: 1.46 | AC30: 0 | AD30: 0 | AE30: 0 | AF30: 1.46 | AG30: 0 | AH30: 1.46 | AI30: 2.5 | AJ30: 0 | AK30: 0 | AL30: 0 | AM30: 0 | AN30: 1.46 | AO30: 0 | AP30: 0 | AQ30: 0 | AR30: 1.46 | AS30: 0 | AT30: 1.46 | AU30: 0 | AV30: 0 | AW30: 0 | AX30: 0 | AY30: 0 | AZ30: 0 | BA30: 0 | BB30: 0 | BC30: 0 | BD30: 0 | BE30: 0 | BF30: 0 | BG30: 150 | BH30: 0 | BI30: 0 | BJ30: 0 | BK30: 0 | BL30: 0 | BM30: 0 | BP30: 0 | BQ30: 0 | BT30: 0 | BU30: 0 | BX30: 0 | BY30: 0 | BZ30: 0 | CA30: 0 | CB30: 0 | CC30: 0 | CD30: 0 | CE30: 0 | CF30: 0 | CG30: 0 | CH30: 0 | CI30: 0 | CJ30: 0 | CK30: 0 | CL30: 0 | CM30: 0 | CN30: 0 | CO30: 0 | CP30: 0 | CQ30: 0 | CR30: 0
A31: 30 | B31: 040 | C31: Baluti - Jambu Hulu (Paku) | D31: baluti – jambu hulu paku | E31: Baluti, Jambu Hilir, Jambu Hulu | F31: Kandangan, Padang Batung | G31: 3 | H31: 2 | I31: 3778 | J31: 0 | K31: 1 | L31: 2296 | M31: 1621.3 | N31: 3589.2 | O31: 57.6 | P31: 2614.4 | Q31: 0 | R31: 0 | S31: 0 | T31: 0 | U31: 0 | V31: 4.07 | W31: 3.5 | X31: 4.07 | Y31: 0 | Z31: 0 | AA31: 0 | AB31: 0 | AC31: 4.07 | AD31: 0 | AE31: 0 | AF31: 0 | AG31: 1 | AH31: 4.07 | AI31: 3.5 | AJ31: 4.07 | AK31: 0 | AL31: 0 | AM31: 0 | AN31: 0 | AO31: 0 | AP31: 4.07 | AQ31: 0 | AR31: 0 | AS31: 1 | AT31: 4.07 | AU31: 0 | AV31: 0 | AW31: 4.0700002 | AX31: 0 | AY31: 0.5 | AZ31: 1.8 | BA31: 1.27 | BB31: 0.5 | BC31: 2.3 | BD31: 1.77 | BE31: 0.56511056 | BF31: 0.43488944 | BG31: 150 | BH31: 0.5 | BI31: 1.8 | BJ31: 1.27 | BK31: 0.5 | BL31: 1 | BM31: 1 | BN31: 2023 | BO31: 1 | BP31: 1 | BQ31: 1 | BR31: 2023 | BS31: 2 | BT31: 1 | BU31: 1 | BV31: 2023 | BW31: 3 | BX31: 0 | BY31: 0 | BZ31: 1 | CA31: 0 | CB31: 0 | CC31: 0 | CD31: 0 | CE31: 0 | CF31: 0 | CG31: 0 | CH31: 0 | CI31: 0 | CJ31: 1 | CK31: 0 | CL31: 0 | CM31: 0 | CN31: 0 | CO31: 0 | CP31: 0 | CQ31: 0 | CR31: 0
A32: 31 | B32: 191 | C32: Bamban (Tibung) - Martajiwa | D32: bamban tibung – martajiwa | E32: Bamban | F32: Angkinang | G32: 1 | H32: 1 | I32: 499 | J32: 0 | K32: 0 | L32: 3513.6 | M32: 1365.5 | N32: 13272.8 | O32: 739.2 | P32: 11409.9 | Q32: 0 | R32: 0 | S32: 0 | T32: 0 | U32: 0 | V32: 0.66 | W32: 3 | X32: 0.66 | Y32: 0 | Z32: 0 | AA32: 0 | AB32: 0 | AC32: 0 | AD32: 0.1 | AE32: 0 | AF32: 0.56 | AG32: 0.15151515 | AH32: 0.66 | AI32: 3 | AJ32: 0.1 | AK32: 0 | AL32: 0 | AM32: 0.56 | AN32: 0 | AO32: 0 | AP32: 0.1 | AQ32: 0 | AR32: 0.56 | AS32: 0.15151515 | AT32: 0.66 | AU32: 0 | AV32: 0 | AW32: 0.1 | AX32: 0 | AY32: 0 | AZ32: 0 | BA32: 0.1 | BB32: 0 | BC32: 0 | BD32: 0.1 | BE32: 0 | BF32: 1 | BG32: 150 | BH32: 0 | BI32: 0 | BJ32: 0.1 | BK32: 0 | BL32: 0 | BM32: 0 | BP32: 0 | BQ32: 0 | BT32: 0 | BU32: 0 | BX32: 0 | BY32: 0 | BZ32: 0 | CA32: 0 | CB32: 0 | CC32: 0 | CD32: 0 | CE32: 0 | CF32: 0 | CG32: 0 | CH32: 0 | CI32: 0 | CJ32: 0 | CK32: 0 | CL32: 0 | CM32: 1 | CN32: 0 | CO32: 0 | CP32: 0 | CQ32: 1 | CR32: 0
A33: 32 | B33: 176 | C33: Bamban Selatan - Pakuan | D33: bamban selatan – pakuan | E33: Angkinang, Bamban Selatan, Pakuan Timur | F33: Angkinang, Telaga Langsat | G33: 3 | H33: 2 | I33: 1568 | J33: 0 | K33: 1 | L33: 2719.8 | M33: 2340.2 | N33: 12479 | O33: 1116.4 | P33: 10616.1 | Q33: 0 | R33: 0 | S33: 0 | T33: 0 | U33: 0 | V33: 2.09 | W33: 3 | X33: 2.09 | Y33: 0 | Z33: 0 | AA33: 0 | AB33: 0 | AC33: 0 | AD33: 2.09 | AE33: 0 | AF33: 0 | AG33: 1 | AH33: 2.09 | AI33: 3 | AJ33: 2.09 | AK33: 0 | AL33: 0 | AM33: 0 | AN33: 0 | AO33: 0 | AP33: 2.09 | AQ33: 0 | AR33: 0 | AS33: 1 | AT33: 2.09 | AU33: 0 | AV33: 0 | AW33: 2.0899999 | AX33: 0 | AY33: 0 | AZ33: 1.89 | BA33: 0.2 | BB33: 0 | BC33: 1.89 | BD33: 0.2 | BE33: 0.90430622 | BF33: 0.095693782 | BG33: 150 | BH33: 0 | BI33: 1.89 | BJ33: 0.2 | BK33: 0 | BL33: 1 | BM33: 1 | BN33: 2023 | BO33: 1 | BP33: 1 | BQ33: 2 | BR33: 2024 | BS33: 1 | BT33: 1 | BU33: 3 | BV33: 2025 | BW33: 1 | BX33: 0 | BY33: 0 | BZ33: 1 | CA33: 1 | CB33: 1 | CC33: 0 | CD33: 0 | CE33: 1 | CF33: 1 | CG33: 1 | CH33: 0 | CI33: 0 | CJ33: 0 | CK33: 0 | CL33: 0 | CM33: 0 | CN33: 1 | CO33: 0 | CP33: 1 | CQ33: 0 | CR33: 0
A34: 33 | B34: 199 | C34: Bamban Selatan - Pakuan Balunan | D34: bamban selatan – pakuan balunan | E34: Bamban Selatan | F34: Angkinang | G34: 1 | H34: 1 | I34: 447 | J34: 0 | K34: 1 | L34: 3639.6 | M34: 2038.8 | N34: 13398.9 | O34: 865.2 | P34: 11536 | Q34: 0 | R34: 0 | S34: 0 | T34: 0 | U34: 0 | V34: 1.71 | W34: 3 | X34: 1.71 | Y34: 0 | Z34: 0 | AA34: 0 | AB34: 0 | AC34: 0 | AD34: 1.71 | AE34: 0 | AF34: 0 | AG34: 1 | AH34: 1.71 | AI34: 3 | AJ34: 1.71 | AK34: 0 | AL34: 0 | AM34: 0 | AN34: 0 | AO34: 0.51 | AP34: 1.2 | AQ34: 0 | AR34: 0 | AS34: 1 | AT34: 1.71 | AU34: 0 | AV34: 0 | AW34: 1.71 | AX34: 0 | AY34: 0.5 | AZ34: 1.21 | BA34: 0 | BB34: 0 | BC34: 1.71 | BD34: 0 | BE34: 1 | BF34: 0 | BG34: 150 | BH34: 0.5 | BI34: 1.21 | BJ34: 0 | BK34: 0 | BL34: 0 | BM34: 0 | BP34: 0 | BQ34: 0 | BT34: 0 | BU34: 0 | BX34: 0 | BY34: 0 | BZ34: 0 | CA34: 0 | CB34: 0 | CC34: 0 | CD34: 0 | CE34: 0 | CF34: 0 | CG34: 0 | CH34: 0 | CI34: 0 | CJ34: 0 | CK34: 0 | CL34: 0 | CM34: 0 | CN34: 0 | CO34: 0 | CP34: 0 | CQ34: 0 | CR34: 0
A35: 34 | B35: 174 | C35: Bamban Selatan - Tanggang - Panggang Hijau | D35: bamban selatan – tanggang – panggang hijau | E35: Bamban, Bamban Selatan, Kayu Abang | F35: Angkinang | G35: 3 | H35: 1 | I35: 1733 | J35: 0 | K35: 1 | L35: 4613.6 | M35: 2943.6 | N35: 13008.9 | O35: 1839.2 | P35: 11146 | Q35: 0 | R35: 0 | S35: 0 | T35: 0 | U35: 0 | V35: 3.58 | W35: 3 | X35: 1.1 | Y35: 0 | Z35: 0 | AA35: 2.48 | AB35: 0 | AC35: 0.2 | AD35: 0.8 | AE35: 0.1 | AF35: 2.48 | AG35: 0.27932961 | AH35: 3.58 | AI35: 3 | AJ35: 1.1 | AK35: 0 | AL35: 0 | AM35: 2.48 | AN35: 0 | AO35: 0 | AP35: 1 | AQ35: 0.1 | AR35: 2.48 | AS35: 0.27932961 | AT35: 3.58 | AU35: 0 | AV35: 0 | AW35: 1.1 | AX35: 0 | AY35: 0 | AZ35: 1 | BA35: 0.1 | BB35: 0 | BC35: 1 | BD35: 0.1 | BE35: 0.90909091 | BF35: 0.090909092 | BG35: 150 | BH35: 0 | BI35: 1 | BJ35: 0.1 | BK35: 0 | BL35: 0 | BM35: 0 | BP35: 0 | BQ35: 0 | BT35: 0 | BU35: 0 | BX35: 0 | BY35: 0 | BZ35: 0 | CA35: 0 | CB35: 0 | CC35: 0 | CD35: 0 | CE35: 0 | CF35: 0 | CG35: 0 | CH35: 0 | CI35: 0 | CJ35: 0 | CK35: 0 | CL35: 0 | CM35: 0 | CN35: 0 | CO35: 0 | CP35: 0 | CQ35: 0 | CR35: 0
A36: 35 | B36: 181 | C36: Bamban Tengah - Lok Nyiur | D36: bamban tengah – lok nyiur | E36: Bamban, Kayu Abang | F36: Angkinang | G36: 2 | H36: 1 | I36: 1286 | J36: 0 | K36: 1 | L36: 3704 | M36: 1555.9 | N36: 13463.2 | O36: 929.6 | P36: 11600.3 | Q36: 0 | R36: 0 | S36: 0 | T36: 0 | U36: 0 | V36: 1.26 | W36: 3.5 | X36: 1 | Y36: 0 | Z36: 0.26 | AA36: 0 | AB36: 0 | AC36: 0 | AD36: 0.8 | AE36: 0.2 | AF36: 0.26 | AG36: 0.63492063 | AH36: 1.26 | AI36: 3.5 | AJ36: 1 | AK36: 0 | AL36: 0.26 | AM36: 0 | AN36: 0 | AO36: 0.2 | AP36: 0.6 | AQ36: 0.2 | AR36: 0.26 | AS36: 0.63492063 | AT36: 1.26 | AU36: 0.25999999 | AV36: 0 | AW36: 1 | AX36: 0 | AY36: 0 | AZ36: 0.69999999 | BA36: 0.30000001 | BB36: 0.25999999 | BC36: 0.69999999 | BD36: 0.56 | BE36: 0.55555555 | BF36: 0.44444445 | BG36: 150 | BH36: 0 | BI36: 0.69999999 | BJ36: 0.30000001 | BK36: 0 | BL36: 0 | BM36: 0 | BP36: 0 | BQ36: 0 | BT36: 0 | BU36: 0 | BX36: 0 | BY36: 0 | BZ36: 0 | CA36: 0 | CB36: 0 | CC36: 0 | CD36: 0 | CE36: 0 | CF36: 0 | CG36: 0 | CH36: 0 | CI36: 0 | CJ36: 0 | CK36: 0 | CL36: 0 | CM36: 1 | CN36: 0 | CO36: 0 | CP36: 0 | CQ36: 1 | CR36: 0
A37: 36 | B37: 177 | C37: Bamban Utara - Longawang | D37: bamban utara – longawang | E37: Bamban Utara, Longawang, Pandulangan | F37: Angkinang, Telaga Langsat | G37: 3 | H37: 2 | I37: 1579 | J37: 0 | K37: 1 | L37: 4916.4 | M37: 1098.2 | N37: 14675.6 | O37: 222.1 | P37: 12812.7 | Q37: 0 | R37: 0 | S37: 0 | T37: 0 | U37: 0 | V37: 2.11 | W37: 3.5 | X37: 2.11 | Y37: 0 | Z37: 0 | AA37: 0 | AB37: 0 | AC37: 2.11 | AD37: 0 | AE37: 0 | AF37: 0 | AG37: 1 | AH37: 2.11 | AI37: 3.5 | AJ37: 2.11 | AK37: 0 | AL37: 0 | AM37: 0 | AN37: 0 | AO37: 0 | AP37: 2.11 | AQ37: 0 | AR37: 0 | AS37: 1 | AT37: 2.11 | AU37: 0 | AV37: 0 | AW37: 2.1099999 | AX37: 0 | AY37: 0 | AZ37: 2.01 | BA37: 0.1 | BB37: 0 | BC37: 2.01 | BD37: 0.1 | BE37: 0.95260663 | BF37: 0.047393366 | BG37: 150 | BH37: 0 | BI37: 2.01 | BJ37: 0.1 | BK37: 0 | BL37: 0 | BM37: 0 | BP37: 0 | BQ37: 0 | BT37: 0 | BU37: 0 | BX37: 0 | BY37: 0 | BZ37: 0 | CA37: 0 | CB37: 0 | CC37: 0 | CD37: 0 | CE37: 0 | CF37: 0 | CG37: 0 | CH37: 0 | CI37: 0 | CJ37: 0 | CK37: 0 | CL37: 0 | CM37: 0 | CN37: 0 | CO37: 0 | CP37: 0 | CQ37: 0 | CR37: 0
A38: 37 | B38: 112 | C38: Bangga TMMD | D38: bangga | E38: Telaga Bidadari | F38: Sungai Raya | G38: 1 | H38: 1 | I38: 668 | J38: 0 | K38: 0 | L38: 3386.3 | M38: 3536.4 | N38: 1759.6 | O38: 1501.9 | P38: 3431.5 | Q38: 0 | R38: 0 | S38: 0 | T38: 0 | U38: 0 | V38: 0.79 | W38: 3.5 | X38: 0.79 | Y38: 0 | Z38: 0 | AA38: 0 | AB38: 0 | AC38: 0 | AD38: 0.79 | AE38: 0 | AF38: 0 | AG38: 1 | AH38: 0.79 | AI38: 3.5 | AJ38: 0.79 | AK38: 0 | AL38: 0 | AM38: 0 | AN38: 0 | AO38: 0 | AP38: 0 | AQ38: 0.79 | AR38: 0 | AS38: 0 | AT38: 0.79 | AU38: 0 | AV38: 0 | AW38: 0.79000002 | AX38: 0 | AY38: 0 | AZ38: 0 | BA38: 0.79000002 | BB38: 0 | BC38: 0 | BD38: 0.79000002 | BE38: 0 | BF38: 1 | BG38: 150 | BH38: 0 | BI38: 0 | BJ38: 0.79000002 | BK38: 0 | BL38: 0 | BM38: 0 | BP38: 0 | BQ38: 0 | BT38: 0 | BU38: 0 | BX38: 0 | BY38: 0 | BZ38: 0 | CA38: 0 | CB38: 0 | CC38: 0 | CD38: 0 | CE38: 0 | CF38: 0 | CG38: 0 | CH38: 0 | CI38: 0 | CJ38: 0 | CK38: 0 | CL38: 0 | CM38: 0 | CN38: 0 | CO38: 0 | CP38: 0 | CQ38: 0 | CR38: 0
A39: 38 | B39: 341 | C39: Banua Hanyar - Ds. Tanjung Selor | D39: banua hanyar – desa tanjung selor | E39: Banua Hanyar, Tanjung Selor | F39: Daha Barat, Daha Selatan | G39: 2 | H39: 2 | I39: 1716 | J39: 0 | K39: 0 | Q39: 1 | R39: 1 | S39: 1 | T39: 1 | U39: 1 | V39: 5.61 | W39: 3 | X39: 0 | Y39: 0 | Z39: 0 | AA39: 0 | AB39: 5.61 | AC39: 0 | AD39: 0 | AE39: 0 | AF39: 5.61 | AG39: 0 | AH39: 5.61 | AI39: 3 | AJ39: 0 | AK39: 0 | AL39: 0 | AM39: 0 | AN39: 5.61 | AO39: 0 | AP39: 0 | AQ39: 0 | AR39: 5.61 | AS39: 0 | AT39: 5.61 | AU39: 0 | AV39: 0 | AW39: 0 | AX39: 0 | AY39: 0 | AZ39: 0 | BA39: 0 | BB39: 0 | BC39: 0 | BD39: 0 | BE39: 0 | BF39: 0 | BG39: 150 | BH39: 0 | BI39: 0 | BJ39: 0 | BK39: 0 | BL39: 0 | BM39: 0 | BP39: 0 | BQ39: 0 | BT39: 0 | BU39: 0 | BX39: 0 | BY39: 0 | BZ39: 0 | CA39: 0 | CB39: 0 | CC39: 0 | CD39: 0 | CE39: 0 | CF39: 0 | CG39: 0 | CH39: 0 | CI39: 0 | CJ39: 0 | CK39: 0 | CL39: 0 | CM39: 0 | CN39: 0 | CO39: 0 | CP39: 0 | CQ39: 0 | CR39: 0
A40: 39 | B40: 243 | C40: Banua Kambang - Ds. Wasah Tengah | D40: banua kambang – desa wasah tengah | E40: Wasah Hulu, Wasah Tengah | F40: Simpur | G40: 2 | H40: 1 | I40: 1057 | J40: 0 | K40: 1 | L40: 2640.6 | M40: 1440.1 | N40: 3946.6 | O40: 946.5 | P40: 4542.4 | Q40: 0 | R40: 0 | S40: 0 | T40: 0 | U40: 0 | V40: 1.39 | W40: 3 | X40: 0 | Y40: 0 | Z40: 0 | AA40: 1.39 | AB40: 0 | AC40: 0 | AD40: 0 | AE40: 0 | AF40: 1.39 | AG40: 0 | AH40: 1.39 | AI40: 3 | AJ40: 1.39 | AK40: 0 | AL40: 0 | AM40: 0 | AN40: 0 | AO40: 1.39 | AP40: 0 | AQ40: 0 | AR40: 0 | AS40: 1 | AT40: 1.39 | AU40: 0 | AV40: 0 | AW40: 1.39 | AX40: 0 | AY40: 0.40000001 | AZ40: 0.49000001 | BA40: 0.5 | BB40: 0 | BC40: 0.89000002 | BD40: 0.5 | BE40: 0.64028777 | BF40: 0.35971223 | BG40: 150 | BH40: 0.40000001 | BI40: 0.49000001 | BJ40: 0.5 | BK40: 0 | BL40: 0 | BM40: 0 | BP40: 1 | BQ40: 1 | BR40: 2024 | BS40: 1 | BT40: 1 | BU40: 1 | BV40: 2024 | BW40: 2 | BX40: 0 | BY40: 0 | BZ40: 0 | CA40: 1 | CB40: 0 | CC40: 0 | CD40: 0 | CE40: 0 | CF40: 0 | CG40: 0 | CH40: 0 | CI40: 0 | CJ40: 0 | CK40: 1 | CL40: 0 | CM40: 0 | CN40: 0 | CO40: 0 | CP40: 0 | CQ40: 0 | CR40: 0
...

Sheet model_2023_2024
A1: no | B1: nomor_ruas | C1: nama_ruas | D1: nama_ruas_norm | E1: desa_yang_dilalui | F1: kecamatan_yang_dilalui | G1: jumlah_desa_yang_dilalui | H1: jumlah_kecamatan_yang_dilalui | I1: jumlah_penduduk_dilayani | J1: terhubung_ruas_provinsi | K1: terhubung_ruas_nasional | L1: jarak_pasar_m | M1: jarak_puskesmas_m | N1: jarak_rsud_m | O1: jarak_sd_smp_m | P1: jarak_ibukota_m | Q1: akses_terputus_ibukota | R1: akses_terputus_pasar | S1: akses_terputus_puskesmas | T1: akses_terputus_rsud | U1: akses_terputus_sd_smp | V1: panjang_km_2023 | W1: lebar_m_2023 | X1: hotmix_km_2023 | Y1: lapen_km_2023 | Z1: beton_km_2023 | AA1: telford_kerikil_km_2023 | AB1: tanah_belum_tembus_km_2023 | AC1: baik_km_2023 | AD1: sedang_km_2023 | AE1: rusak_ringan_km_2023 | AF1: rusak_berat_km_2023 | AG1: jalan_mantap_pct_2023 | AH1: prior_handled_any_pre2024 | AI1: prior_handled_count_pre2024 | AJ1: prior_handled_last_year_pre2024 | AK1: years_since_last_handled_pre2024 | AL1: handled_any_2024 | AM1: handled_pl_2024 | AN1: handled_tender_2024
A2: 1 | B2: 035 | C2: AES Nasution | D2: aes nasution | E2: Baluti | F2: Kandangan | G2: 1 | H2: 1 | I2: 1377 | J2: 0 | K2: 0 | L2: 714.1 | M2: 954.7 | N2: 1467.1 | O2: 166.2 | P2: 395.8 | Q2: 0 | R2: 0 | S2: 0 | T2: 0 | U2: 0 | V2: 0.24 | W2: 3.5 | X2: 0.24 | Y2: 0 | Z2: 0 | AA2: 0 | AB2: 0 | AC2: 0.24 | AD2: 0 | AE2: 0 | AF2: 0 | AG2: 1 | AH2: 0 | AI2: 0 | AL2: 1 | AM2: 0 | AN2: 1
A3: 2 | B3: 234 | C3: Air Miris - Ds. Wasah Hilir | D3: air miris – desa wasah hilir | E3: Wasah Hilir, Wasah Tengah | F3: Simpur | G3: 2 | H3: 1 | I3: 1294 | J3: 0 | K3: 1 | L3: 961.1 | M3: 2012.5 | N3: 5681 | O3: 667.2 | P3: 6453.8 | Q3: 0 | R3: 0 | S3: 0 | T3: 0 | U3: 0 | V3: 1.06 | W3: 3 | X3: 1.06 | Y3: 0 | Z3: 0 | AA3: 0 | AB3: 0 | AC3: 1.06 | AD3: 0 | AE3: 0 | AF3: 0 | AG3: 1 | AH3: 0 | AI3: 0 | AL3: 0 | AM3: 0 | AN3: 0
A4: 3 | B4: 345 | C4: Al - Ikhlas - Ds. Baluti | D4: al – ikhlas – desa baluti | E4: Baluti, Tibung Raya | F4: Kandangan | G4: 2 | H4: 1 | I4: 2315 | J4: 0 | K4: 0 | L4: 1257.5 | M4: 1407.6 | N4: 1286.8 | O4: 425.9 | P4: 1575.8 | Q4: 0 | R4: 0 | S4: 0 | T4: 0 | U4: 0 | V4: 0.38 | W4: 3.5 | X4: 0 | Y4: 0 | Z4: 0 | AA4: 0.38 | AB4: 0 | AC4: 0 | AD4: 0 | AE4: 0 | AF4: 0.38 | AG4: 0 | AH4: 0 | AI4: 0 | AL4: 1 | AM4: 0 | AN4: 1
A5: 4 | B5: 008 | C5: Aluh Idut | D5: aluh idut | E5: Kandangan Barat, Kandangan Kota, Kandangan Utara | F5: Kandangan | G5: 3 | H5: 1 | I5: 6205 | J5: 0 | K5: 1 | L5: 1109.5 | M5: 461.8 | N5: 2807.8 | O5: 138.8 | P5: 944.9 | Q5: 0 | R5: 0 | S5: 0 | T5: 0 | U5: 0 | V5: 1.34 | W5: 5 | X5: 1.34 | Y5: 0 | Z5: 0 | AA5: 0 | AB5: 0 | AC5: 1.34 | AD5: 0 | AE5: 0 | AF5: 0 | AG5: 1 | AH5: 0 | AI5: 0 | AL5: 0 | AM5: 0 | AN5: 0
A6: 5 | B6: 032 | C6: Amawang Kanan - Wasah Hulu | D6: amawang kanan – wasah hulu | E6: Amawang Kanan, Wasah Hulu | F6: Kandangan, Simpur | G6: 2 | H6: 2 | I6: 1122 | J6: 0 | K6: 1 | L6: 3281 | M6: 1687.3 | N6: 2540.2 | O6: 459.8 | P6: 3136 | Q6: 0 | R6: 0 | S6: 0 | T6: 0 | U6: 0 | V6: 3.17 | W6: 3.5 | X6: 3.17 | Y6: 0 | Z6: 0 | AA6: 0 | AB6: 0 | AC6: 3.17 | AD6: 0 | AE6: 0 | AF6: 0 | AG6: 1 | AH6: 1 | AI6: 1 | AJ6: 2023 | AK6: 1 | AL6: 0 | AM6: 0 | AN6: 0
A7: 6 | B7: 031 | C7: Amawang Muka - Getek | D7: amawang muka – getek | E7: Amawang Kiri, Amawang Kiri Muka, Bariang, Sungai Paring | F7: Kandangan | G7: 4 | H7: 1 | I7: 2479 | J7: 0 | K7: 0 | L7: 4114.1 | M7: 3726.6 | N7: 5380 | O7: 191.1 | P7: 3795.8 | Q7: 0 | R7: 0 | S7: 0 | T7: 0 | U7: 0 | V7: 5.41 | W7: 3.5 | X7: 5.41 | Y7: 0 | Z7: 0 | AA7: 0 | AB7: 0 | AC7: 5.41 | AD7: 0 | AE7: 0 | AF7: 0 | AG7: 1 | AH7: 1 | AI7: 2 | AJ7: 2023 | AK7: 1 | AL7: 0 | AM7: 0 | AN7: 0
A8: 7 | B8: 149 | C8: Ambarai - Madang | D8: ambarai – madang | E8: Karang Jawa, Madang | F8: Padang Batung | G8: 2 | H8: 1 | I8: 1088 | J8: 0 | K8: 0 | L8: 2381.2 | M8: 3220.9 | N8: 7125.8 | O8: 1028.5 | P8: 5524.6 | Q8: 0 | R8: 0 | S8: 0 | T8: 0 | U8: 0 | V8: 1.74 | W8: 3.5 | X8: 1.74 | Y8: 0 | Z8: 0 | AA8: 0 | AB8: 0 | AC8: 1.74 | AD8: 0 | AE8: 0 | AF8: 0 | AG8: 1 | AH8: 0 | AI8: 0 | AL8: 1 | AM8: 1 | AN8: 0
A9: 8 | B9: 187 | C9: AMD - Ds. Lok Binuang | D9: amd – desa lok binuang | E9: Lok Binuang, Telaga Langsat | F9: Telaga Langsat | G9: 2 | H9: 1 | I9: 763 | J9: 0 | K9: 0 | L9: 4179.5 | M9: 2818.2 | N9: 13938.7 | O9: 1329.4 | P9: 12075.8 | Q9: 0 | R9: 0 | S9: 0 | T9: 0 | U9: 0 | V9: 1.57 | W9: 3 | X9: 0.1 | Y9: 0 | Z9: 0 | AA9: 1.47 | AB9: 0 | AC9: 0 | AD9: 0 | AE9: 0 | AF9: 1.57 | AG9: 0 | AH9: 0 | AI9: 0 | AL9: 0 | AM9: 0 | AN9: 0
A10: 9 | B10: 214 | C10: Amparaya - Karangan - Hanau | D10: amparaya – karangan – hanau | E10: Amparaya, Panjampang Bahagia | F10: Simpur | G10: 2 | H10: 1 | I10: 1032 | J10: 0 | K10: 0 | L10: 4608.7 | M10: 5179.2 | N10: 10259.5 | O10: 1207.7 | P10: 10424.2 | Q10: 0 | R10: 0 | S10: 0 | T10: 0 | U10: 0 | V10: 4.36 | W10: 3.5 | X10: 4.36 | Y10: 0 | Z10: 0 | AA10: 0 | AB10: 0 | AC10: 0 | AD10: 4.16 | AE10: 0.2 | AF10: 0 | AG10: 0.95412844 | AH10: 1 | AI10: 3 | AJ10: 2023 | AK10: 1 | AL10: 0 | AM10: 0 | AN10: 0
A11: 10 | B11: 011 | C11: Anggrek | D11: anggrek | E11: Kandangan Kota, Kandangan Utara | F11: Kandangan | G11: 2 | H11: 1 | I11: 4331 | J11: 0 | K11: 0 | L11: 781.6 | M11: 796.9 | N11: 2773.5 | O11: 196.3 | P11: 910.6 | Q11: 0 | R11: 0 | S11: 0 | T11: 0 | U11: 0 | V11: 0.23 | W11: 3 | X11: 0.23 | Y11: 0 | Z11: 0 | AA11: 0 | AB11: 0 | AC11: 0.23 | AD11: 0 | AE11: 0 | AF11: 0 | AG11: 1 | AH11: 1 | AI11: 1 | AJ11: 2023 | AK11: 1 | AL11: 0 | AM11: 0 | AN11: 0
A12: 11 | B12: 346 | C12: Angkakai - Ds. Amawang Kiri | D12: angkakai – desa amawang kiri | E12: Amawang Kiri | F12: Kandangan | G12: 1 | H12: 1 | I12: 786 | J12: 0 | K12: 0 | L12: 4664.3 | M12: 3176.4 | N12: 5196.4 | O12: 490.7 | P12: 4346 | Q12: 0 | R12: 0 | S12: 0 | T12: 0 | U12: 0 | V12: 0.4 | W12: 3.5 | X12: 0 | Y12: 0 | Z12: 0 | AA12: 0.4 | AB12: 0 | AC12: 0 | AD12: 0 | AE12: 0 | AF12: 0.4 | AG12: 0 | AH12: 0 | AI12: 0 | AL12: 0 | AM12: 0 | AN12: 0
A13: 12 | B13: 178 | C13: Angkinang - Kayu Abang - Panggang Hijau | D13: angkinang – kayu abang – panggang hijau | E13: Angkinang, Kayu Abang, Tawia | F13: Angkinang | G13: 3 | H13: 1 | I13: 2516 | J13: 0 | K13: 1 | L13: 4170.6 | M13: 4803.9 | N13: 12260.5 | O13: 1030.9 | P13: 10397.6 | Q13: 0 | R13: 0 | S13: 0 | T13: 0 | U13: 0 | V13: 7 | W13: 3 | X13: 5.4 | Y13: 0 | Z13: 0 | AA13: 1.6 | AB13: 0 | AC13: 0 | AD13: 2.6 | AE13: 1.4 | AF13: 3 | AG13: 0.37142857 | AH13: 1 | AI13: 2 | AJ13: 2023 | AK13: 1 | AL13: 1 | AM13: 1 | AN13: 0
A14: 13 | B14: 175 | C14: Angkinang - Telaga Langsat | D14: angkinang – telaga langsat | E14: Angkinang, Angkinang Selatan, Lok Binuang, Mandala, Telaga Langsat | F14: Angkinang, Telaga Langsat | G14: 5 | H14: 2 | I14: 2430 | J14: 0 | K14: 1 | L14: 2807.7 | M14: 2660.1 | N14: 12566.9 | O14: 42.4 | P14: 10704 | Q14: 0 | R14: 0 | S14: 0 | T14: 0 | U14: 0 | V14: 5.58 | W14: 3 | X14: 5.58 | Y14: 0 | Z14: 0 | AA14: 0 | AB14: 0 | AC14: 0 | AD14: 3.78 | AE14: 1.8 | AF14: 0 | AG14: 0.67741935 | AH14: 1 | AI14: 1 | AJ14: 2021 | AK14: 3 | AL14: 1 | AM14: 1 | AN14: 1
A15: 14 | B15: 172 | C15: Angkinang Selatan - Tawia - Wawaran | D15: angkinang selatan – tawia – wawaran | E15: Angkinang Selatan, Bakarung, Taniran Kubah, Tawia | F15: Angkinang | G15: 4 | H15: 1 | I15: 3114 | J15: 0 | K15: 0 | L15: 3473.9 | M15: 4541 | N15: 11563.7 | O15: 1798.1 | P15: 9700.8 | Q15: 0 | R15: 0 | S15: 0 | T15: 0 | U15: 0 | V15: 5.88 | W15: 3 | X15: 5.88 | Y15: 0 | Z15: 0 | AA15: 0 | AB15: 0 | AC15: 0 | AD15: 4.48 | AE15: 1.4 | AF15: 0 | AG15: 0.76190476 | AH15: 1 | AI15: 1 | AJ15: 2023 | AK15: 1 | AL15: 1 | AM15: 0 | AN15: 1
A16: 15 | B16: 347 | C16: Anjiran Rantauan - Ds. Taniran Tengah | D16: anjiran rantauan – desa taniran tengah | E16: Taniran Selatan | F16: Angkinang | G16: 1 | H16: 1 | I16: 545 | J16: 0 | K16: 1 | L16: 2869.7 | M16: 3143.5 | N16: 8536.5 | O16: 474.2 | P16: 6673.6 | Q16: 0 | R16: 0 | S16: 0 | T16: 0 | U16: 0 | V16: 1.21 | W16: 3.5 | X16: 1.21 | Y16: 0 | Z16: 0 | AA16: 0 | AB16: 0 | AC16: 0 | AD16: 0 | AE16: 0 | AF16: 1.21 | AG16: 0 | AH16: 0 | AI16: 0 | AL16: 0 | AM16: 0 | AN16: 0
A17: 16 | B17: 097 | C17: Asam Cangkuk - Telaga Bidadari | D17: asam cangkuk – telaga bidadari | E17: Amawang Kanan, Telaga Bidadari, Wasah Hulu | F17: Kandangan, Simpur, Sungai Raya | G17: 3 | H17: 3 | I17: 1790 | J17: 0 | K17: 0 | L17: 2965.8 | M17: 2977.4 | N17: 2083.4 | O17: 862.4 | P17: 3010.9 | Q17: 0 | R17: 0 | S17: 0 | T17: 0 | U17: 0 | V17: 0.83 | W17: 2 | X17: 0.83 | Y17: 0 | Z17: 0 | AA17: 0 | AB17: 0 | AC17: 0 | AD17: 0 | AE17: 0 | AF17: 0.83 | AG17: 0 | AH17: 0 | AI17: 0 | AL17: 0 | AM17: 0 | AN17: 0
A18: 17 | B18: 348 | C18: Asam Duhat - Ds. Pantai Ulin | D18: asam duhat – desa pantai ulin | E18: Pantai Ulin | F18: Simpur | G18: 1 | H18: 1 | I18: 708 | J18: 0 | K18: 0 | L18: 4362.9 | M18: 4148.6 | N18: 11085.9 | O18: 532.9 | P18: 7234.7 | Q18: 0 | R18: 0 | S18: 0 | T18: 0 | U18: 0 | V18: 1.11 | W18: 3.5 | X18: 0 | Y18: 0 | Z18: 0 | AA18: 1.11 | AB18: 0 | AC18: 0 | AD18: 0 | AE18: 0 | AF18: 1.11 | AG18: 0 | AH18: 1 | AI18: 2 | AJ18: 2023 | AK18: 1 | AL18: 0 | AM18: 0 | AN18: 0
A19: 18 | B19: 123 | C19: Asam Seranggan - Asam Tamiyang | D19: asam seranggan – asam tamiyang | E19: Asam, Tamiyang | F19: Sungai Raya | G19: 2 | H19: 1 | I19: 797 | J19: 0 | K19: 0 | L19: 7415 | M19: 4953 | N19: 8268.7 | O19: 979.8 | P19: 12484.5 | Q19: 0 | R19: 0 | S19: 0 | T19: 0 | U19: 0 | V19: 1.02 | W19: 3 | X19: 0 | Y19: 0 | Z19: 0 | AA19: 1.02 | AB19: 0 | AC19: 0 | AD19: 0 | AE19: 0 | AF19: 1.02 | AG19: 0 | AH19: 1 | AI19: 1 | AJ19: 2022 | AK19: 2 | AL19: 0 | AM19: 0 | AN19: 0
A20: 19 | B20: 238 | C20: At-Taubah - Ds. Kapuh | D20: at – taubah – desa kapuh | E20: Kapuh | F20: Simpur | G20: 1 | H20: 1 | I20: 682 | J20: 0 | K20: 0 | L20: 2565.8 | M20: 3045 | N20: 3705.6 | O20: 527.9 | P20: 5104.2 | Q20: 0 | R20: 0 | S20: 0 | T20: 0 | U20: 0 | V20: 0.47 | W20: 3 | X20: 0.47 | Y20: 0 | Z20: 0 | AA20: 0 | AB20: 0 | AC20: 0.47 | AD20: 0 | AE20: 0 | AF20: 0 | AG20: 1 | AH20: 0 | AI20: 0 | AL20: 0 | AM20: 0 | AN20: 0
A21: 20 | B21: 343 | C21: Badaun - Ds. Bjayau Lama | D21: badaun – desa bjayau lama | E21: Bajayau Lama | F21: Daha Barat | G21: 1 | H21: 1 | I21: 426 | J21: 0 | K21: 0 | O21: 612 | Q21: 1 | R21: 1 | S21: 1 | T21: 1 | U21: 0 | V21: 3.1 | W21: 3 | X21: 0 | Y21: 0 | Z21: 0 | AA21: 0 | AB21: 3.1 | AC21: 0 | AD21: 0 | AE21: 0 | AF21: 3.1 | AG21: 0 | AH21: 0 | AI21: 0 | AL21: 0 | AM21: 0 | AN21: 0
A22: 21 | B22: 249 | C22: Bago Tanggul - Katilang - Teratai | D22: bago tanggul – katilang – teratai | E22: Bago Tanggul, Balanti, Kalumpang, Karang Bulan | F22: Kalumpang | G22: 4 | H22: 1 | I22: 960 | J22: 0 | K22: 0 | L22: 10210.5 | M22: 7816.6 | N22: 20724.2 | O22: 161.6 | P22: 22103.7 | Q22: 0 | R22: 0 | S22: 0 | T22: 0 | U22: 0 | V22: 9.71 | W22: 4 | X22: 7.3 | Y22: 0 | Z22: 0 | AA22: 0 | AB22: 2.41 | AC22: 7.3 | AD22: 0 | AE22: 0 | AF22: 2.41 | AG22: 0.75180227 | AH22: 1 | AI22: 1 | AJ22: 2022 | AK22: 2 | AL22: 0 | AM22: 0 | AN22: 0
A23: 22 | B23: 069 | C23: Baiturrahim Parincahan | D23: baiturrahim parincahan | E23: Kandangan Barat | F23: Kandangan | G23: 1 | H23: 1 | I23: 1874 | J23: 0 | K23: 1 | L23: 2675.7 | M23: 2608.4 | N23: 4437.4 | O23: 935.9 | P23: 2574.5 | Q23: 0 | R23: 0 | S23: 0 | T23: 0 | U23: 0 | V23: 1.42 | W23: 3 | X23: 1.2 | Y23: 0 | Z23: 0 | AA23: 0 | AB23: 0.22 | AC23: 0.4 | AD23: 0 | AE23: 0.8 | AF23: 0.22 | AG23: 0.28169014 | AH23: 1 | AI23: 1 | AJ23: 2023 | AK23: 1 | AL23: 0 | AM23: 0 | AN23: 0
A24: 23 | B24: 340 | C24: Bajayau - Ds. Bajayau Tengah | D24: bajayau – desa bajayau tengah | E24: Bajayau, Bajayau Tengah | F24: Daha Barat | G24: 2 | H24: 1 | I24: 734 | J24: 0 | K24: 0 | L24: 3635.1 | M24: 1570.2 | N24: 17922.5 | O24: 1051.1 | Q24: 1 | R24: 0 | S24: 0 | T24: 0 | U24: 0 | V24: 7.58 | W24: 3.5 | X24: 3.1 | Y24: 0 | Z24: 0 | AA24: 0.1 | AB24: 4.38 | AC24: 3.1 | AD24: 0 | AE24: 0 | AF24: 4.48 | AG24: 0.40897098 | AH24: 1 | AI24: 1 | AJ24: 2023 | AK24: 1 | AL24: 0 | AM24: 0 | AN24: 0
A25: 24 | B25: 167 | C25: Bakarung - Rantauan | D25: bakarung – rantauan | E25: Bakarung, Gambah Dalam Barat, Gambah Luar, Taniran Selatan | F25: Angkinang, Kandangan | G25: 4 | H25: 2 | I25: 2506 | J25: 1 | K25: 1 | L25: 1752.4 | M25: 2792.8 | N25: 8362.7 | O25: 1550.7 | P25: 6499.8 | Q25: 0 | R25: 0 | S25: 0 | T25: 0 | U25: 0 | V25: 3.03 | W25: 3.5 | X25: 3.03 | Y25: 0 | Z25: 0 | AA25: 0 | AB25: 0 | AC25: 3.03 | AD25: 0 | AE25: 0 | AF25: 0 | AG25: 1 | AH25: 1 | AI25: 2 | AJ25: 2023 | AK25: 1 | AL25: 0 | AM25: 0 | AN25: 0
A26: 25 | B26: 179 | C26: Bakarung -Tabihi - Karang Jawa | D26: bakarung – tabihi – karang jawa | E26: Bakarung, Karang Jawa, Karang Jawa Muka, Tabihi | F26: Angkinang, Padang Batung | G26: 4 | H26: 2 | I26: 2766 | J26: 0 | K26: 1 | L26: 2678.7 | M26: 1551.4 | N26: 5058.9 | O26: 419.1 | P26: 3325.5 | Q26: 0 | R26: 0 | S26: 0 | T26: 0 | U26: 0 | V26: 4.57 | W26: 3.5 | X26: 4.57 | Y26: 0 | Z26: 0 | AA26: 0 | AB26: 0 | AC26: 0 | AD26: 4.57 | AE26: 0 | AF26: 0 | AG26: 1 | AH26: 1 | AI26: 1 | AJ26: 2023 | AK26: 1 | AL26: 0 | AM26: 0 | AN26: 0
A27: 26 | B27: 056 | C27: Bakarung Tengah - Karang Jawa | D27: bakarung tengah – karang jawa | E27: Gambah Luar, Gambah Luar Muka, Karang Jawa Muka | F27: Kandangan, Padang Batung | G27: 3 | H27: 2 | I27: 1780 | J27: 0 | K27: 1 | L27: 2368.5 | M27: 1835.5 | N27: 4559.7 | O27: 89.1 | P27: 2826.2 | Q27: 0 | R27: 0 | S27: 0 | T27: 0 | U27: 0 | V27: 3.77 | W27: 3.5 | X27: 3.77 | Y27: 0 | Z27: 0 | AA27: 0 | AB27: 0 | AC27: 3.77 | AD27: 0 | AE27: 0 | AF27: 0 | AG27: 1 | AH27: 1 | AI27: 3 | AJ27: 2023 | AK27: 1 | AL27: 0 | AM27: 0 | AN27: 0
A28: 27 | B28: 219 | C28: Balaimas - Hanau | D28: balaimas – hanau | E28: Panjampang Bahagia, Pantai Ulin | F28: Simpur | G28: 2 | H28: 1 | I28: 1150 | J28: 0 | K28: 0 | L28: 6620.7 | M28: 4762 | N28: 8803.8 | O28: 1614.2 | P28: 8968.5 | Q28: 0 | R28: 0 | S28: 0 | T28: 0 | U28: 0 | V28: 2.33 | W28: 3.5 | X28: 2.33 | Y28: 0 | Z28: 0 | AA28: 0 | AB28: 0 | AC28: 2.33 | AD28: 0 | AE28: 0 | AF28: 0 | AG28: 1 | AH28: 1 | AI28: 2 | AJ28: 2023 | AK28: 1 | AL28: 0 | AM28: 0 | AN28: 0
A29: 28 | B29: 251 | C29: Balanti - (Ex. P3DT) | D29: balanti – p3dt | E29: Balanti, Karang Bulan | F29: Kalumpang | G29: 2 | H29: 1 | I29: 426 | J29: 0 | K29: 0 | L29: 4304.7 | M29: 1910.8 | N29: 14818.3 | O29: 1026 | P29: 16197.8 | Q29: 0 | R29: 0 | S29: 0 | T29: 0 | U29: 0 | V29: 1.66 | W29: 3 | X29: 1.66 | Y29: 0 | Z29: 0 | AA29: 0 | AB29: 0 | AC29: 1.66 | AD29: 0 | AE29: 0 | AF29: 0 | AG29: 1 | AH29: 1 | AI29: 1 | AJ29: 2022 | AK29: 2 | AL29: 0 | AM29: 0 | AN29: 0
A30: 29 | B30: 256 | C30: Balimau - Murung Dalam | D30: balimau – murung dalam | E30: Balimau | F30: Kalumpang | G30: 1 | H30: 1 | I30: 310 | J30: 0 | K30: 0 | L30: 8506.9 | M30: 6113.1 | N30: 19020.6 | O30: 1650.5 | P30: 20400.1 | Q30: 0 | R30: 0 | S30: 0 | T30: 0 | U30: 0 | V30: 1.46 | W30: 2.5 | X30: 0 | Y30: 0 | Z30: 0 | AA30: 0 | AB30: 1.46 | AC30: 0 | AD30: 0 | AE30: 0 | AF30: 1.46 | AG30: 0 | AH30: 0 | AI30: 0 | AL30: 0 | AM30: 0 | AN30: 0
A31: 30 | B31: 040 | C31: Baluti - Jambu Hulu (Paku) | D31: baluti – jambu hulu paku | E31: Baluti, Jambu Hilir, Jambu Hulu | F31: Kandangan, Padang Batung | G31: 3 | H31: 2 | I31: 3778 | J31: 0 | K31: 1 | L31: 2296 | M31: 1621.3 | N31: 3589.2 | O31: 57.6 | P31: 2614.4 | Q31: 0 | R31: 0 | S31: 0 | T31: 0 | U31: 0 | V31: 4.07 | W31: 3.5 | X31: 4.07 | Y31: 0 | Z31: 0 | AA31: 0 | AB31: 0 | AC31: 4.07 | AD31: 0 | AE31: 0 | AF31: 0 | AG31: 1 | AH31: 1 | AI31: 1 | AJ31: 2023 | AK31: 1 | AL31: 0 | AM31: 0 | AN31: 0
